Workbook
Name LST_LOC: Locations!$A$5:$A$34
Name LST_TRE: Treasuries!$A$5:$A$34
Name LST_PM: Payment_Methods!$A$5:$A$19
Name LST_CC: Cost_Centers!$A$5:$A$34
Name LST_SUP: Suppliers!$A$5:$A$154
Name LST_CUS: Customers!$A$5:$A$104
Name LST_EMP: Employees!$A$5:$A$104
Name LST_ACCT: COA!$A$5:$A$254
Name LST_USER: Users!$B$5:$B$44
Name LST_UNIT: Units!$A$5:$A$34
Name LST_ITEM: Items!$A$5:$A$304
Name ST_DRAFT: Lists!$A$5
Name ST_APPR: Lists!$A$6
Name ST_POST: Lists!$A$7
Name ST_REV: Lists!$A$8
Name ST_CANC: Lists!$A$9
Name LST_STATUS: Lists!$A$5:$A$9
Name LST_VTYPE: Lists!$E$5:$E$11
Name LST_ITYPE: Lists!$J$5:$J$7
Name LST_EMODE: Lists!$N$5:$N$6
Name LST_YN: Lists!$R$5:$R$6
Name LST_CATS: Lists!$T$5:$T$8
Name LST_JETYPE: Lists!$W$5:$W$14
Name LST_RSN: Lists!$Y$5:$Y$13
Name LST_RES: Lists!$AA$5:$AA$7
Name LST_CF: Lists!$AC$5:$AC$9
Name LST_TTYPE: Lists!$AF$5:$AF$7
Name LST_LTYPE: Lists!$AH$5:$AH$8
Name LST_ATYPE: Lists!$AJ$5:$AJ$10
Name LST_PMTYPE: Lists!$AM$5:$AM$8
Name LST_ROLE: Lists!$AO$5:$AO$14
Name S_FYStart: Settings!$C$8
Name S_From: Settings!$C$9
Name S_To: Settings!$C$10
Name S_Branch: Settings!$C$11
Name S_CC: Settings!$C$12
Name S_PeriodID: Settings!$C$13
Name S_PFrom: Settings!$C$14
Name S_PTo: Settings!$C$15
Name S_CogsMethod: Settings!$C$16
Name S_Tol: Settings!$C$17
Name S_PlatDays: Settings!$C$18
Name S_CashTol: Settings!$C$19
Name S_Mode: Settings!$C$20
Name S_VATOn: Tax_Settings!$C$5
Name S_VATRate: Tax_Settings!$C$6
Name S_VATF: Tax_Settings!$C$7
Name LG_Acct: GL_Ledger!$B$4
Name LG_Party: GL_Ledger!$B$5
Name LG_Loc: GL_Ledger!$B$6
Name LG_CC: GL_Ledger!$B$7
Name LG_From: GL_Ledger!$B$8
Name LG_To: GL_Ledger!$B$9
Name LG_Open: GL_Ledger!$E$5
Name TB_From: Trial_Balance!$C$4
Name TB_To: Trial_Balance!$C$5
Name TB_Branch: Trial_Balance!$C$6
Name TB_CC: Trial_Balance!$C$7
Name TB_LOCC: Trial_Balance!$E$4
Name TB_CCC: Trial_Balance!$E$5

Sheet Dashboard
B1: لوحة التحكم الرئيسية - مطاعم ستاموني
B2: ="الفترة: "&YEAR(S_From)&"-"&TEXT(MONTH(S_From),"00")&"-"&TEXT(DAY(S_From),"00")&" → "&YEAR(S_To)&"-"&TEXT(MONTH(S_To),"00")&"-"&TEXT(DAY(S_To),"00")&" | الفرع: "&S_Branch&" | وضع البيانات: "&S_Mode&" | العملة: EGP"
B3: =IS_Banner
B5: مبيعات آخر يوم مسجل | D5: إجمالي مبيعات الفترة | F5: صافي المبيعات | H5: عدد الطلبات | J5: متوسط قيمة الطلب | L5: ="مجمل الربح"&IF(CK_Critical>0," (أولي)","")
B6: =SUMIFS(Sales_Daily!$Z:$Z,Sales_Daily!$B:$B,_xlfn.MAXIFS(Sales_Daily!$B:$B,Sales_Daily!$B:$B,"<="&S_To,Sales_Daily!$AY:$AY,1),Sales_Daily!$AY:$AY,1) | D6: =IS_GrossSales | F6: =IS_NetSales | H6: =SUMIFS(Sales_Daily!$D:$D,Sales_Daily!$B:$B,">="&S_From,Sales_Daily!$B:$B,"<="&S_To,Sales_Daily!$AY:$AY,1) | J6: =IF(H6=0,"غير متوفر",SUMIFS(Sales_Daily!$AA:$AA,Sales_Daily!$B:$B,">="&S_From,Sales_Daily!$B:$B,"<="&S_To,Sales_Daily!$AY:$AY,1)/H6) | L6: =IS_GrossProfit
B7: =IF(_xlfn.MAXIFS(Sales_Daily!$B:$B,Sales_Daily!$B:$B,"<="&S_To,Sales_Daily!$AY:$AY,1)=0,"لا مبيعات مرحلة","بتاريخ "&YEAR(_xlfn.MAXIFS(Sales_Daily!$B:$B,Sales_Daily!$B:$B,"<="&S_To,Sales_Daily!$AY:$AY,1))&"-"&TEXT(MONTH(_xlfn.MAXIFS(Sales_Daily!$B:$B,Sales_Daily!$B:$B,"<="&S_To,Sales_Daily!$AY:$AY,1)),"00")&"-"&TEXT(DAY(_xlfn.MAXIFS(Sales_Daily!$B:$B,Sales_Daily!$B:$B,"<="&S_To,Sales_Daily!$AY:$AY,1)),"00")) | D7: قبل الخصومات والمرتجعات | F7: =IF(IS_NetSales_P=0,"المقارنة: لا توجد فترة سابقة","السابقة: "&TEXT(IS_NetSales_P,"#,##0")&" ("&TEXT((IS_NetSales-IS_NetSales_P)/ABS(IS_NetSales_P),"+0%;-0%")&")") | H7: من تقارير المبيعات المرحلة | J7: صافي المبيعات ÷ عدد الطلبات | L7: =IF(IS_GrossProfit_P=0,"المقارنة: لا توجد فترة سابقة","السابقة: "&TEXT(IS_GrossProfit_P,"#,##0")&" ("&TEXT((IS_GrossProfit-IS_GrossProfit_P)/ABS(IS_GrossProfit_P),"+0%;-0%")&")")
B9: ="صافي الربح"&IF(CK_Critical>0," (أولي - غير مؤكد)"," (مؤكد)") | D9: نسبة تكلفة المبيعات | F9: المصروفات التشغيلية | H9: قيمة المخزون | J9: مستحقات منصات التوصيل والبطاقات | L9: أرصدة الموردين
B10: =IS_NetProfit | D10: =IF(IS_NetSales=0,"-",IS_COGS/IS_NetSales) | F10: =IS_OpEx | H10: =(SUMIFS(GL_Journal!$S:$S,GL_Journal!$G:$G,">=1400",GL_Journal!$G:$G,"<=1499",GL_Journal!$D:$D,"<="&S_To)-SUMIFS(GL_Journal!$T:$T,GL_Journal!$G:$G,">=1400",GL_Journal!$G:$G,"<=1499",GL_Journal!$D:$D,"<="&S_To)) | J10: =(SUMIFS(GL_Journal!$S:$S,GL_Journal!$G:$G,">=1302",GL_Journal!$G:$G,"<=1304",GL_Journal!$D:$D,"<="&S_To)-SUMIFS(GL_Journal!$T:$T,GL_Journal!$G:$G,">=1302",GL_Journal!$G:$G,"<=1304",GL_Journal!$D:$D,"<="&S_To)) | L10: =SB_Total
B11: =IF(IS_NetProfit_P=0,"المقارنة: لا توجد فترة سابقة","السابقة: "&TEXT(IS_NetProfit_P,"#,##0")&" ("&TEXT((IS_NetProfit-IS_NetProfit_P)/ABS(IS_NetProfit_P),"+0%;-0%")&")") | D11: تكلفة المبيعات ÷ صافي المبيعات | F11: =IF(IS_OpEx_P=0,"المقارنة: لا توجد فترة سابقة","السابقة: "&TEXT(IS_OpEx_P,"#,##0")&" ("&TEXT((IS_OpEx-IS_OpEx_P)/ABS(IS_OpEx_P),"+0%;-0%")&")") | H11: حسابات 1400-1499 (دفتريًا) | J11: 1302-1304 غير محصلة | L11: إجمالي المستحق للموردين
B13: الهالك (طبيعي وغير طبيعي) | D13: فروق الجرد (مخزون) | F13: فروق الخزائن (عجز - زيادة) | H13: أرصدة البنوك | J13: النقدية بالخزائن | L13: مديونيات العملاء المستحقة
B14: =(SUMIFS(GL_Journal!$S:$S,GL_Journal!$G:$G,">=5200",GL_Journal!$G:$G,"<=5299",GL_Journal!$D:$D,">="&S_From,GL_Journal!$D:$D,"<="&S_To)-SUMIFS(GL_Journal!$T:$T,GL_Journal!$G:$G,">=5200",GL_Journal!$G:$G,"<=5299",GL_Journal!$D:$D,">="&S_From,GL_Journal!$D:$D,"<="&S_To)) | D14: =(SUMIFS(GL_Journal!$S:$S,GL_Journal!$G:$G,">=5400",GL_Journal!$G:$G,"<=5499",GL_Journal!$D:$D,">="&S_From,GL_Journal!$D:$D,"<="&S_To)-SUMIFS(GL_Journal!$T:$T,GL_Journal!$G:$G,">=5400",GL_Journal!$G:$G,"<=5499",GL_Journal!$D:$D,">="&S_From,GL_Journal!$D:$D,"<="&S_To)) | F14: =(SUMIFS(GL_Journal!$S:$S,GL_Journal!$G:$G,ACC_CASH_SHORT,GL_Journal!$D:$D,">="&S_From,GL_Journal!$D:$D,"<="&S_To)-SUMIFS(GL_Journal!$T:$T,GL_Journal!$G:$G,ACC_CASH_SHORT,GL_Journal!$D:$D,">="&S_From,GL_Journal!$D:$D,"<="&S_To))-(-(SUMIFS(GL_Journal!$S:$S,GL_Journal!$G:$G,ACC_CASH_OVER,GL_Journal!$D:$D,">="&S_From,GL_Journal!$D:$D,"<="&S_To)-SUMIFS(GL_Journal!$T:$T,GL_Journal!$G:$G,ACC_CASH_OVER,GL_Journal!$D:$D,">="&S_From,GL_Journal!$D:$D,"<="&S_To))) | H14: =(SUMIFS(GL_Journal!$S:$S,GL_Journal!$G:$G,">=1200",GL_Journal!$G:$G,"<=1299",GL_Journal!$D:$D,"<="&S_To)-SUMIFS(GL_Journal!$T:$T,GL_Journal!$G:$G,">=1200",GL_Journal!$G:$G,"<=1299",GL_Journal!$D:$D,"<="&S_To)) | J14: =(SUMIFS(GL_Journal!$S:$S,GL_Journal!$G:$G,">=1100",GL_Journal!$G:$G,"<=1199",GL_Journal!$D:$D,"<="&S_To)-SUMIFS(GL_Journal!$T:$T,GL_Journal!$G:$G,">=1100",GL_Journal!$G:$G,"<=1199",GL_Journal!$D:$D,"<="&S_To)) | L14: =(SUMIFS(GL_Journal!$S:$S,GL_Journal!$G:$G,ACC_CUSTOMERS,GL_Journal!$D:$D,"<="&S_To)-SUMIFS(GL_Journal!$T:$T,GL_Journal!$G:$G,ACC_CUSTOMERS,GL_Journal!$D:$D,"<="&S_To))
B15: المرحلة 2 للتفصيل | D15: موجب = عجز | F15: موجب = عجز صافٍ | L15: حساب 1301
A21: رصيد كل خزينة وبنك (Treasury_Balances)
B22: الكود | C22: الاسم | F22: الرصيد الختامي | H22: تنبيه
B23: =Treasury_Balances!$A$9 | C23: =Treasury_Balances!$B$9 | F23: =Treasury_Balances!$I$9 | H23: =Treasury_Balances!$L$9
B24: =Treasury_Balances!$A$10 | C24: =Treasury_Balances!$B$10 | F24: =Treasury_Balances!$I$10 | H24: =Treasury_Balances!$L$10
B25: =Treasury_Balances!$A$11 | C25: =Treasury_Balances!$B$11 | F25: =Treasury_Balances!$I$11 | H25: =Treasury_Balances!$L$11
B26: =Treasury_Balances!$A$12 | C26: =Treasury_Balances!$B$12 | F26: =Treasury_Balances!$I$12 | H26: =Treasury_Balances!$L$12
B27: =Treasury_Balances!$A$13 | C27: =Treasury_Balances!$B$13 | F27: =Treasury_Balances!$I$13 | H27: =Treasury_Balances!$L$13
B28: =Treasury_Balances!$A$14 | C28: =Treasury_Balances!$B$14 | F28: =Treasury_Balances!$I$14 | H28: =Treasury_Balances!$L$14
B29: =Treasury_Balances!$A$15 | C29: =Treasury_Balances!$B$15 | F29: =Treasury_Balances!$I$15 | H29: =Treasury_Balances!$L$15
B30: =Treasury_Balances!$A$16 | C30: =Treasury_Balances!$B$16 | F30: =Treasury_Balances!$I$16 | H30: =Treasury_Balances!$L$16
B31: =Treasury_Balances!$A$17 | C31: =Treasury_Balances!$B$17 | F31: =Treasury_Balances!$I$17 | H31: =Treasury_Balances!$L$17
B32: =Treasury_Balances!$A$18 | C32: =Treasury_Balances!$B$18 | F32: =Treasury_Balances!$I$18 | H32: =Treasury_Balances!$L$18
A35: مقارنة أداء الفروع (من قائمة الدخل - بدون توزيع تكاليف الإدارة)
B36: الفرع | C36: إجمالي المبيعات | D36: صافي المبيعات | E36: تكلفة المبيعات | F36: مجمل الربح | G36: % مجمل الربح | H36: مصروفات مباشرة | I36: الربح التشغيلي
B37: =Income_Statement!I$11 | C37: =IF(B37="","",Income_Statement!I17) | D37: =IF(B37="","",Income_Statement!I20) | E37: =IF(B37="","",Income_Statement!I26) | F37: =IF(B37="","",Income_Statement!I27) | G37: =IF(B37="","",IF(D37=0,0,F37/D37)) | H37: =IF(B37="","",Income_Statement!I38) | I37: =IF(B37="","",Income_Statement!I39)
B38: =Income_Statement!J$11 | C38: =IF(B38="","",Income_Statement!J17) | D38: =IF(B38="","",Income_Statement!J20) | E38: =IF(B38="","",Income_Statement!J26) | F38: =IF(B38="","",Income_Statement!J27) | G38: =IF(B38="","",IF(D38=0,0,F38/D38)) | H38: =IF(B38="","",Income_Statement!J38) | I38: =IF(B38="","",Income_Statement!J39)
B39: =Income_Statement!K$11 | C39: =IF(B39="","",Income_Statement!K17) | D39: =IF(B39="","",Income_Statement!K20) | E39: =IF(B39="","",Income_Statement!K26) | F39: =IF(B39="","",Income_Statement!K27) | G39: =IF(B39="","",IF(D39=0,0,F39/D39)) | H39: =IF(B39="","",Income_Statement!K38) | I39: =IF(B39="","",Income_Statement!K39)
B40: =Income_Statement!L$11 | C40: =IF(B40="","",Income_Statement!L17) | D40: =IF(B40="","",Income_Statement!L20) | E40: =IF(B40="","",Income_Statement!L26) | F40: =IF(B40="","",Income_Statement!L27) | G40: =IF(B40="","",IF(D40=0,0,F40/D40)) | H40: =IF(B40="","",Income_Statement!L38) | I40: =IF(B40="","",Income_Statement!L39)
B41: =Income_Statement!M$11 | C41: =IF(B41="","",Income_Statement!M17) | D41: =IF(B41="","",Income_Statement!M20) | E41: =IF(B41="","",Income_Statement!M26) | F41: =IF(B41="","",Income_Statement!M27) | G41: =IF(B41="","",IF(D41=0,0,F41/D41)) | H41: =IF(B41="","",Income_Statement!M38) | I41: =IF(B41="","",Income_Statement!M39)
B42: =Income_Statement!N$11 | C42: =IF(B42="","",Income_Statement!N17) | D42: =IF(B42="","",Income_Statement!N20) | E42: =IF(B42="","",Income_Statement!N26) | F42: =IF(B42="","",Income_Statement!N27) | G42: =IF(B42="","",IF(D42=0,0,F42/D42)) | H42: =IF(B42="","",Income_Statement!N38) | I42: =IF(B42="","",Income_Statement!N39)
A44: المصروفات التشغيلية حسب النوع | E44: الحالية | F44: السابقة
B45: =Income_Statement!$A$29 | E45: =Income_Statement!$E$29 | F45: =Income_Statement!$G$29
B46: =Income_Statement!$A$30 | E46: =Income_Statement!$E$30 | F46: =Income_Statement!$G$30
B47: =Income_Statement!$A$31 | E47: =Income_Statement!$E$31 | F47: =Income_Statement!$G$31
B48: =Income_Statement!$A$32 | E48: =Income_Statement!$E$32 | F48: =Income_Statement!$G$32
B49: =Income_Statement!$A$33 | E49: =Income_Statement!$E$33 | F49: =Income_Statement!$G$33
B50: =Income_Statement!$A$34 | E50: =Income_Statement!$E$34 | F50: =Income_Statement!$G$34
B51: =Income_Statement!$A$35 | E51: =Income_Statement!$E$35 | F51: =Income_Statement!$G$35
...

Sheet Guide
A1: دليل الأوراق (Sheet Guide)
A2: ابدأ من هنا: ماذا تفعل كل ورقة وماذا تدخل فيها. التفاصيل الكاملة في ملفات docs
A4: الورقة | B4: المجموعة | C4: الوظيفة | D4: المدخلات | E4: المخرجات | F4: ملاحظات
A5: Dashboard | B5: A/K | C5: لوحة التحكم الرئيسية | D5: لا إدخال | E5: مؤشرات ورسوم وتنبيهات | F5: —
A6: Guide | B6: A | C6: هذا الدليل وخريطة الأوراق | D6: — | E6: — | F6: —
A7: System_Map | B7: A | C7: خريطة النظام: الوحدات والمستندات والقيود | D7: — | E7: — | F7: —
A8: Settings | B8: A | C8: فترة التقارير وطريقة التكلفة وحدود السماح | D8: الخلايا الصفراء | E8: تتحكم في كل التقارير | F8: —
A9: Lists | B9: A | C9: القوائم المنسدلة وحالات المستندات | D9: المسؤول فقط | E9: — | F9: —
A10: COA | B10: A/J | C10: دليل الحسابات الموحد | D10: حساب جديد في صف فارغ | E10: يغذي القوائم والتقارير | F10: —
A11: Locations | B11: A | C11: الفروع والمخازن والمطابخ والإدارة | D11: صف لكل موقع | E11: — | F11: —
A12: Treasuries | B12: A/C | C12: الخزائن والبنوك وحساب كل منها | D12: صف لكل خزينة | E12: — | F12: —
A13: Users / Permissions | B13: A | C13: المستخدمون ومصفوفة الصلاحيات | D13: — | E13: — | F13: —
A14: Suppliers / Customers / Employees | B14: A | C14: الموردون والعملاء والموظفون | D14: — | E14: — | F14: —
A15: Items / Units / Unit_Conversions / Unit_Converter | B15: A/E | C15: الأصناف والوحدات والتحويل المعتمد ومحوّل مضبوط | D15: — | E15: — | F15: —
... A37: PR, Quotations, PO, GRN, Inventory_Moves, Stock_Count, Recipes, Production, Payroll, Fixed_Assets, Advances_Custody | B37: المراحل 2-3 | C37: هياكل جاهزة للمراحل القادمة | D37: — | E37: — | F37: لا تؤثر على الدفاتر بعد

Sheet System_Map
A1: خريطة النظام (System Map)
A2: الوحدات المالية والتشغيلية وحركة البيانات بينها
A4: الوحدة | B4: المستند الذي يبدأ الحركة | C4: من يعدّه | D4: من يعتمده | E4: القيد المحاسبي الناتج | F4: الأثر (خزينة / مخزون / تكلفة / ربح) | G4: التقارير | H4: المرحلة
A5: مبيعات الفرع اليومية | B5: تقرير مبيعات يومي (15) | C5: الكاشير / أمين الصندوق | D5: مدير الفرع ← المحاسب يرحّل | E5: مدين: تحصيل كل وسيلة دفع (خزينة / بطاقات / منصات) + خصومات + مرتجعات | دائن: إيراد كل فئة (+ضريبة) | F5: نقدية↑ أو مستحقات↑ | ربح↑ | مخزون: لا (التكلفة في التسوية الدورية) | G5: Income_Statement, Dashboard, Daily_Recon | H5: 1
A6: مطابقة المبيعات اليومية | B6: كشف إقفال (14) + تقرير الجهاز/المنصة | C6: أمين الصندوق | D6: مدير الفرع | E6: لا قيد؛ الفرق يُسجل بسند عجز/زيادة | F6: يكشف الفروق قبل أن تدخل الأرباح | G6: Daily_Recon, Close_Checklist | H6: 1
A7: تسوية المنصات والبطاقات | B7: كشف تسوية (16) | C7: المحاسب | D7: المدير المالي | E7: مدين: بنك + عمولة + خصومات (+1309) | دائن: مستحقات المنصة | F7: نقدية↑ | مستحقات↓ | ربح↓ بقيمة العمولة فقط | G7: Platform_Settlements, Balance_Sheet | H7: 1
A8: الخزائن وسندات القبض والصرف | B8: سند قبض (11) / صرف (12) | C8: أمين الصندوق | D8: المعتمد ← المحاسب | E8: قبض: مدين خزينة / دائن الحساب المقابل | صرف: العكس | F8: حسب الحساب المقابل | G8: Treasury_Balances, GL_Ledger | H8: 1
A9: التحويل بين الخزائن والبنوك | B9: إذن تحويل (13) | C9: المسلِّم والمستلم | D9: المعتمد | E9: مدين: الخزينة المستلمة / دائن: المسلِّمة | F9: لا أثر على الإيراد أو المصروف | G9: Treasury_Balances, Cash_Flow (تحويلات داخلية = 0) | H9: 1
A10: عجز وزيادة الخزينة | B10: كشف إقفال (14) + تسوية (30) | C10: أمين الصندوق | D10: مدير الفرع + المدير المالي | E10: عجز: مدين 6910 / دائن خزينة | زيادة: مدين خزينة / دائن 4210 | F10: نقدية↓/↑ | ربح↓/↑ | G10: Cash_Close, Dashboard | H10: 1
A11: المصروفات والمستحقات | B11: نموذج مصروفات (17) | C11: مقدم الطلب | D11: مدير الفرع/الإدارة ← المحاسب | E11: فوري: مدين مصروف / دائن خزينة | آجل: دائن 2201 | F11: ربح↓ بتاريخ الاستحقاق | نقدية بتاريخ الدفع | G11: Expenses, Income_Statement | H11: 1
A12: المشتريات (طلب ← أمر ← استلام ← فاتورة ← سداد) | B12: نماذج 1 و2 و3 + فاتورة المورد | C12: مشرف المشتريات / أمين المخزن | D12: معتمد الشراء ← المدير المالي | E12: فاتورة: مدين مخزون/أصل/مصروف / دائن 2101 | الطلب والأمر لا قيد لهما | F12: مخزون↑ والتزام↑ | لا أثر على الربح | G12: Supplier_Invoices, Supplier_Balances | H12: 1 (الفاتورة) / 2 (الطلب والأمر والاستلام)
A13: الموردون ودفعاتهم | B13: سند صرف (12) | C13: مشرف المشتريات | D13: المدير المالي | E13: مدين 2101 / دائن خزينة أو بنك | F13: التزام↓ ونقدية↓ | G13: Supplier_Payments, Supplier_Balances | H13: 1
A14: المخزون والتحويلات | B14: إذن استلام (3) / صرف (4) / تحويل (5) / جرد (10) | C14: أمين المخزن | D14: معتمد الصرف | E14: التحويل: مدين مخزون المستلم / دائن المسلِّم (بالتكلفة الدفترية) | F14: لا إيراد ولا تكلفة مبيعات | G14: Inventory_Moves (المرحلة 2) | H14: 2
A15: السنتر كيتشن والإنتاج | B15: نماذج 6 و7 و8 و9 | C15: مدير الإنتاج | D15: المدير المالي (للهالك غير الطبيعي) | E15: خام ← تحت التشغيل ← تام ← مخزون الفرع، والهالك بحساب منفصل | F15: لا إيراد؛ التكلفة تنتقل مع المنتج | G15: Production, Recipes (المرحلة 2) | H15: 2
... A21: التقارير | B21: — | C21: المحاسب | D21: — | E21: تقرأ من دفتر اليومية فقط | F21: — | G21: Trial_Balance, Income_Statement, Balance_Sheet, Cash_Flow, Dashboard | H21: 1

Sheet User_Manual
A1: دليل التشغيل المبسط لغير المحاسبين
A2: 14 إجراء بالترتيب: من المسؤول، المستند، الخطوات، الخانات، النتيجة، التحقق، الأخطاء الشائعة، المعتمِد
A4: م | B4: الإجراء | C4: من المسؤول؟ | D4: المستند المطلوب | E4: الخطوات بالترتيب | F4: الخانات التي يملؤها | G4: النتيجة المتوقعة | H4: كيف يعرف أنها تمت صحيحة | I4: الأخطاء الشائعة | J4: من يعتمد
A5: 1 | B5: كيف يبدأ المستخدم يومه | C5: مدير الفرع + أمين الصندوق (+ المحاسب في الإدارة) | D5: لا مستند (فحص بداية اليوم) | E5: 1) افتح ملف Satamoni_Financial_Management_System من رابط Google Sheets الذي شاركه المدير المالي. 2) افتح ورقة Dashboard وانظر الشريط الأعلى: إذا ظهر (نتائج أولية) فهذا طبيعي أثناء الشهر. 3) اقرأ قسم التنبيهات (Alerts): الأحمر = مشكلة تحتاج إجراء، الأصفر = مراجعة، الأخضر = سليم. 4) افتح نموذج الورق الجديد لليوم (تقرير المبيعات اليومي - نموذج 15) وتأكد أن الرقم المطبوع عليه هو التالي بعد آخر رقم استُخدم. 5) أمين الصندوق يعدّ الفكّة ويسجلها في كشف إقفال الأمس ليتأكد من الرصيد الافتتاحي. | F5: لا خانات. | G5: تعرف حالة الفرع والتنبيهات المعلقة قبل بدء البيع. | H5: لا توجد تنبيهات حمراء تخص فرعك. | I5: • البدء دون قراءة التنبيهات • استخدام رقم نموذج مكرر (النظام يمنع ترحيله) | J5: —
A6: 2 | B6: كيف يسجل المبيعات | C6: أمين الصندوق/الكاشير يعد، مدير الفرع يعتمد، المحاسب يرحّل | D6: تقرير مبيعات يومي (نموذج 15) | E6: 1) في آخر اليوم: اطبع تقرير نقطة البيع (أو اجمع الأرقام) واملأ نموذج 15: المبيعات حسب الفئة، الخصومات، المرتجعات، ثم التحصيل حسب وسيلة الدفع. 2) تأكد على الورق أن (مجموع وسائل الدفع = صافي المبيعات). 3) يوقّع الكاشير ومدير الفرع. 4) في Google Sheets افتح ورقة Sales_Daily وأضف صفًا جديدًا في أول صف فارغ (الخلايا الصفراء فقط). 5) املأ: رقم التقرير، التاريخ، الفرع، عدد الطلبات، المبيعات لكل فئة، الخصومات، المرتجعات، ثم تحصيل كل وسيلة دفع. 6) اختر الحالة (مسودة) ثم أخبر مدير الفرع ليختار نفسه في خانة (المعتمد) ويغيّر الحالة إلى (معتمد). 7) المحاسب يراجع ويغيّر الحالة إلى (مرحل) ويكتب اسمه في خانة (المحاسب المرحِّل). | F6: رقم التقرير، التاريخ، الفرع، عدد الطلبات، أربع خانات للفئات، الخصومات، المرتجعات، خمس خانات لوسائل الدفع، الحالة، المُعِد، المعتمد، المرحِّل، مرجع الورق. | G6: عمود (فحص المستند) فارغ، وعمود (فرق صافي - وسائل الدفع) = 0.00، وتظهر أسطر القيد في GL_Journal. | H6: Dashboard: مبيعات اليوم تساوي ما في النموذج الورقي. | I6: • كتابة الصافي في خانة الإجمالي • نسيان خانة تحصيل المنصة فيظهر فرق • ترك الحالة (مسودة): لن يظهر في التقارير • اختيار فرع خطأ | J6: مدير الفرع (اعتماد) ثم المحاسب (ترحيل)
A7: 3 | B7: كيف يغلق الخزينة | C7: أمين الصندوق يعد، مدير الفرع يعتمد، المحاسب يراجع | D7: كشف إقفال خزينة يومي (نموذج 14)، وعند الفرق نموذج 30 | E7: 1) عدّ النقدية الفعلية بالفئات واملأ نموذج 14. 2) في ورقة Cash_Close أضف صفًا: التاريخ، الخزينة، المبلغ المعدود. 3) اقرأ الرصيد الدفتري ثم عمود (فرق الجرد). إن كان صفرًا انتهيت. 4) إن وُجد فرق: اكتب سبب الفرق والمسؤول وحالة المعالجة، واملأ نموذج 30. 5) المحاسب يسجل في Cash_Vouchers سند (عجز خزينة) أو (زيادة خزينة) ويربط رقمه في Cash_Close. 6) في ورقة Daily_Recon سجل المطابقة اليومية لنقدي وكل وسيلة دفع (المتوقع من المبيعات ← الفعلي). | F7: التاريخ، الخزينة، المبلغ المعدود، السبب، المسؤول، الحالة، رقم سند التسوية. | G7: عمود (فرق متبقٍ بعد التسوية) = 0 ولا ظهور لـ (فحص). | H7: Cash_Close: الصف أخضر بلا تنبيه. Treasury_Balances: رصيد الخزينة = ما عددته. | I7: • إخفاء العجز في تعديل المبيعات • عدم كتابة اسم المسؤول عن الفرق • نسيان ربط رقم سند التسوية | J7: مدير الفرع + المحاسب
A8: 4 | B8: كيف يطلب شراء بضاعة | C8: طالب الشراء (أمين المخزن/مدير الفرع)، معتمد الشراء | D8: طلب شراء (نموذج 1) ثم أمر شراء (نموذج 2) | E8: 1) املأ نموذج 1: الأصناف والكميات والجهة وتاريخ الاحتياج. 2) يوقّع مدير الجهة، ثم يعتمد مشرف المشتريات. 3) مشرف المشتريات يصدر أمر شراء (نموذج 2) للمورد المعتمد ويحتفظ بالصورة. 4) في المرحلة 1: الطلب والأمر ورقيان فقط، ولا يُسجلان محاسبيًا. في المرحلة 2 سيُسجلان في ورقتي PR وPO. | F8: الجهة، التاريخ، الأصناف، الكميات، سبب الطلب. | G8: أمر شراء موقع ومرقم يُسلَّم للمورد. | H8: رقم الأمر مسجل في دفتر الأوامر ويحمل نفس رقم الطلب. | I8: • الشراء بدون أمر شراء • أن يطلب ويعتمد نفس الشخص | J8: معتمد الشراء (مختلف عن الطالب)
A9: 5 | B9: كيف يستلم أمين المخزن البضاعة | C9: أمين المخزن يستلم، مشرف المشتريات يطابق، المحاسب يسجل الفاتورة | D9: إذن استلام مخزني (نموذج 3) + فاتورة المورد | E9: 1) قارن البضاعة الواردة بأمر الشراء: النوع والكمية والصلاحية والجودة. 2) املأ نموذج 3 بالكمية المستلمة والمرفوضة ووقّع مع مندوب المورد. 3) سلّم أصل الإذن للمحاسب مع الفاتورة في نفس اليوم. 4) المحاسب يسجل الفاتورة في Supplier_Invoices: المورد، رقم فاتورة المورد، التاريخ، الحساب المدين (مخزون)، الجهة، الصافي، مراجع الأمر والاستلام. 5) النظام يرفض فاتورة مكررة (نفس المورد ونفس الرقم). | F9: رقم التسجيل، رقم فاتورة المورد، المورد، التاريخ، النوع، الحساب المدين، الجهة، الصافي، الضريبة، الدفع الفوري (للنقدي)، الأمر، الاستلام. | G9: رصيد المورد يزيد بقيمة الفاتورة، ويظهر تاريخ الاستحقاق. | H9: Supplier_Balances: رصيد المورد وتاريخ الاستحقاق. عمود (فحص المستند) فارغ. | I9: • تسجيل الفاتورة قبل الاستلام الفعلي • اختيار حساب مصروف بدل مخزون • تسجيل فاتورة نفسها مرتين | J9: مشرف المشتريات (مطابقة) + المدير المالي
A10: 6 | B10: كيف يصرف المخزن للسنتر كيتشن أو الفروع | C10: أمين المخزن ينفذ، مدير الإنتاج/الفرع يستلم، المعتمد يوقع | D10: طلب صرف إنتاج (6) / إذن صرف (4) / إذن تحويل (5) | E10: 1) الجهة الطالبة تملأ الطلب بالكميات. 2) المعتمد يوقع. 3) أمين المخزن يصرف ويملأ إذن الصرف أو التحويل، ويوقع المستلم على الأصل. 4) تُسلَّم الأصول للمحاسب أسبوعيًا على الأقل لحفظ سجل الحركة. 5) المرحلة 1: ورقيًا فقط ولا يؤثر على الربح. المرحلة 2: تُسجل في Inventory_Moves، وتبقى تكلفة التحويل = التكلفة الدفترية. | F10: الصنف، الوحدة، الكمية، الجهة المصدر والمستلمة. | G10: الكمية تخرج من المخزن وتدخل جهة الاستلام بدون أي إيراد أو تكلفة مبيعات. | H10: لا يوجد في أي قيد حساب إيراد. الرصيد الإجمالي للمخزون لم يتغير. | I10: • الصرف بدون إذن موقع • ترك التحويل مفتوحًا بدون توقيع المستلم | J10: معتمد الصرف
A11: 7 | B11: كيف يتم تسجيل الإنتاج والهالك | C11: مدير الإنتاج يعد، أمين المخزن يتحقق، المدير المالي يعتمد الهالك غير الطبيعي | D11: تقرير إنتاج يومي (7) / تحويل إنتاج (8) / تقرير هالك (9) | E11: 1) يصرف المطبخ المواد حسب الوصفة القياسية. 2) في نهاية اليوم يسجل مدير الإنتاج الكمية المخططة والفعلية والهالك الطبيعي وغير الطبيعي في نموذج 7. 3) يحوّل الإنتاج للفروع بنموذج 8 ويوقع الفرع. 4) الهالك غير الطبيعي يحتاج تحقيقًا واعتمادًا كتابيًا من المدير المالي. 5) المرحلة 2: تسجيل في Production وInventory_Moves مع حساب تكلفة الدفعة وتكلفة الوحدة والفروق. | F11: الوصفة، الكمية المخططة والفعلية، الهالك بنوعيه، الجهة المحولة إليها. | G11: تكلفة المنتج المحوَّل = تكلفة الدفعة ÷ الناتج الصالح؛ الهالك غير الطبيعي يظهر بحساب منفصل. | H11: مقارنة الاستخدام الفعلي بالوصفة القياسية. | I11: • احتساب المنتج المحول مبيعات • إخفاء الهالك داخل الاستخدام | J11: مدير الإنتاج + المدير المالي (غير الطبيعي)
A12: 8 | B12: كيف يتم تسجيل المصروفات | C12: مقدم الطلب يعد، مدير الفرع/الإدارة يوافق، المحاسب يرحّل | D12: نموذج مصروفات (17) + فاتورة/إيصال | E12: 1) املأ نموذج 17 وارفق الفاتورة أو الإيصال. 2) اختر (فوري) إن دُفع الآن، أو (آجل) إن كان مستحقًا ويُسدد لاحقًا. 3) في ورقة Expenses أضف صفًا: رقم المصروف، تاريخ الاستحقاق، الفرع، مركز التكلفة، الحساب، المبلغ، النمط، الخزينة (للفوري)، المستفيد. 4) عند السداد لاحقًا للآجل: في Cash_Vouchers سجل (صرف) بالحساب المقابل 2201 واكتب في (المستند المرتبط) رقم المصروف. 5) لا تسجل هنا شراء أجهزة أو معدات: تُسجل في فواتير الموردين كأصل ثابت. | F12: الرقم، التاريخ، الفرع، مركز التكلفة، حساب المصروف، المبلغ، النمط، الخزينة، المستفيد، البيان. | G12: يظهر المصروف في قائمة الدخل في شهر الاستحقاق، وحالة السداد في عمود (حالة السداد). | H12: Expenses: حالة السداد صحيحة. Income_Statement: المصروف على الفرع المطلوب. | I12: • اختيار حساب غير صحيح • تسجيل الآجل كفوري • نسيان ربط سند السداد | J12: مدير الفرع/الإدارة + المدير المالي
A13: 9 | B13: كيف يتم تسجيل سداد الموردين | C13: مشرف المشتريات يعد، المدير المالي يعتمد، أمين الخزينة ينفذ، المحاسب يرحّل | D13: سند صرف (نموذج 12) أو طلب دفع | E13: 1) راجع Supplier_Balances: رصيد المورد وتاريخ الاستحقاق. 2) املأ نموذج 12 بالمبلغ والمورد والفواتير المسددة. 3) يعتمد المدير المالي، ثم يدفع أمين الخزينة أو يحوّل البنك. 4) في Supplier_Payments أضف صفًا: رقم الدفعة، التاريخ، المورد، الخزينة/البنك، المبلغ، طريقة الدفع، رقم تسجيل الفاتورة المسددة. | F13: رقم الدفعة، التاريخ، المورد، الخزينة/البنك، المبلغ، الطريقة، الفاتورة المسددة. | G13: رصيد المورد ينقص بقيمة الدفعة، ورصيد الخزينة/البنك ينقص. | H13: Supplier_Balances ثم Treasury_Balances. الفرق بين دفتر الموردين الفرعي وحساب 2101 = صفر. | I13: • دفعة تتجاوز الرصيد • السداد قبل الاعتماد • اختيار مورد خطأ | J13: المدير المالي
A14: 10 | B14: كيف يراجع المدير نتائج الفرع | C14: مدير الفرع / الإدارة | D14: لا مستند (مراجعة) | E14: 1) افتح Dashboard وانظر جدول (مقارنة أداء الفروع). 2) افتح Income_Statement واختر الفرع من Settings (S_Branch) لرؤية تفاصيل مصروفاته. 3) قارن الفترة الحالية بالسابقة في الأعمدة الجانبية. 4) انتبه: صافي الربح (أولي) حتى يكتمل الإقفال. | F14: لا. | G14: فهم المبيعات والتكلفة والمصروفات والربح التشغيلي للفرع. | H14: الأرقام تتطابق مع تقارير الفرع الورقية. | I14: • اعتبار الربح الأولي نهائيًا • مقارنة فرعين بدون النظر لتوزيع المصروفات المشتركة | J14: —
A15: 11 | B15: كيف يراجع المحاسب القيود | C15: المحاسب / مراجع الحسابات | D15: لا مستند (مراجعة) | E15: 1) افتح GL_Journal وفلتر عمود (أثر فعلي) على 0 لمعرفة الأسطر المحجوبة وأسبابها. 2) افتح Close_Checklist وعالج كل بند ✖ ثم ⚠. 3) افتح Trial_Balance وتأكد أن الحالة (متوازن). 4) راجع GL_Ledger لحسابات الصندوق والبنوك والموردين. 5) راجع عينة من المستندات الورقية مقابل ما سُجل. | F15: لا. | G15: لا أخطاء حرجة ولا قيود محجوبة بلا تفسير. | H15: Test_Cases كلها (نجح) في الاختبارات الحية. | I15: • ترحيل مستند به تنبيه • تجاهل بنود المراجعة | J15: المدير المالي
A16: 12 | B16: كيف يتم إقفال الشهر | C16: المحاسب يعد، المراجع يراجع، المدير المالي يقفل، الإدارة العليا تعتمد | D16: محضر إقفال شهر (26) | E16: 1) في Settings ضع (بداية الفترة) أول الشهر و(نهاية الفترة) آخر الشهر. 2) سجّل القيود الدورية: تسوية تكلفة المبيعات بعد الجرد، المصروفات المستحقة، إطفاء المقدم، الإهلاك، الرواتب، عمولة المنصات المقدرة. 3) افتح Close_Checklist وعالج كل البنود الحرجة الآلية. 4) للبنود اليدوية (M01-M14): نفّذ الإجراء ثم سجل التأكيد في Close_Confirm. 5) عندما تصبح (جاهزية الإقفال) خضراء: افتح Period_Close، أضف الشهر، انسخ القيم الحية والصقها كقيم في أعمدة (لقطة)، ثم اكتب اسمك والمعتمد الثاني وغيّر الحالة إلى (مقفلة). 6) وقّع محضر الإقفال (نموذج 26) وأرشفه، وأنشئ نسخة احتياطية من الملف (ملف ← إنشاء نسخة). | F16: رقم الفترة، الحالة، المقفِل، التاريخ، المعتمد الثاني، لقطات الإيرادات والربح والمدين والدائن. | G16: الفترة (مقفلة) وأي تغيير لاحق في أرقامها يظهر فورًا كبند حرج. | H16: Close_Checklist: لا بنود حرجة. Period_Close: عمود (تغيّر بعد الإقفال) فارغ. | I16: • الإقفال قبل الجرد • عدم حفظ نسخة احتياطية • تسجيل قيد بأثر رجعي في فترة مقفلة | J16: المدير المالي + الإدارة العليا
... A18: 14 | B18: العمليات التي يجب ألا يقوم بها المستخدم بنفسه | C18: الجميع | D18: — | E18: 1) لا تعدّل أو تحذف مستندًا (مرحل) أو (معكوس). 2) لا تغيّر الحالة إلى (مرحل) لمستند أعددته أو اعتمدته بنفسك. 3) لا تمسح الصيغ (الخلايا الرمادية) ولا تغيّر ترتيب الأعمدة أو تحذف أوراقًا. 4) لا تعدّل أرصدة المخزون يدويًا؛ التسوية بمستند معتمد فقط. 5) لا تغيّر دليل الحسابات أو الأكواد الأساسية؛ هذا للمدير المالي. 6) لا تدخل مبلغًا سالبًا لتصحيح خطأ؛ استخدم عكس المستند. 7) لا تشارك الملف أو تغيّر صلاحياته. 8) لا تغيّر فترة التقارير في Settings ثم تتجاهل أن الجميع يراها. | F18: — | G18: — | H18: — | I18: • — (هذه كلها أخطاء) | J18: —

Sheet Settings
A1: إعدادات النظام (System Settings)
A2: الخلايا الصفراء قابلة للتعديل. فترة التقارير تتحكم في لوحة التحكم وميزان المراجعة وقائمة الدخل وقائمة الإقفال.
B4: الإعداد | C4: القيمة | D4: ملاحظات
B5: اسم المنشأة | C5: مطاعم ستاموني (Satamoni) | D5: للعرض في التقارير
B6: العملة الأساسية | C6: EGP | D6: جنيه مصري
B7: المنطقة الزمنية | C7: Africa/Cairo | D7: اضبطها أيضًا من إعدادات ملف Google Sheets: ملف ← الإعدادات
B8: بداية السنة المالية | C8: 46023 | D8: تُستخدم في الإقفال السنوي
B9: بداية فترة التقارير | C9: 46296 | D9: غيّرها لعرض شهر آخر (يجب أن تكون أول الشهر عند الإقفال)
B10: نهاية فترة التقارير | C10: 46326 | D10: آخر يوم في الفترة؛ هي أيضًا تاريخ الأرصدة في الميزانية
B11: الفرع المختار للتقارير | C11: ALL | D11: ALL = كل المواقع، أو كود موقع مثل BR01
B12: مركز التكلفة المختار | C12: ALL | D12: ALL = كل المراكز، أو كود مثل CC10
B13: رقم الفترة (آلي) | C13: =YEAR(C10)*100+MONTH(C10) | D13: صيغة: سنة*100+شهر، تُستخدم في الإقفال
B14: بداية فترة المقارنة (آلي) | C14: =C9-(C10-C9+1) | D14: فترة سابقة بنفس عدد الأيام
B15: نهاية فترة المقارنة (آلي) | C15: =C9-1
B16: طريقة تسجيل تكلفة المبيعات | C16: PERIODIC | D16: PERIODIC = دوري مُعدّل (النسخة الأولى: قيد شهري بالجرد) | PERPETUAL = مستمر من حركات المخزون (المرحلة 2). لا تجمع بينهما في نفس الفترة.
B17: هامش السماح بالفروق (جنيه) | C17: 0.01 | D17: للمقارنات الحسابية (تقريب)
B18: أيام تنبيه تأخر تسوية المنصات | C18: 14 | D18: تنبيه إن مضى هذا العدد دون تسوية ومستحقات المنصة موجودة
B19: حد فرق الخزينة المسموح (جنيه) | C19: 0 | D19: أي فرق أكبر منه يجب أن يُسجل بسند عجز/زيادة
B20: وضع البيانات | C20: تشغيلي | D20: تجريبي = بيانات الاختبار؛ غيّرها إلى (تشغيلي) بعد تفريغ البيانات التجريبية

Sheet Lists
A1: القوائم المنسدلة وحالات المستندات (Lists & Document Statuses)
A2: هذه القوائم تغذي القوائم المنسدلة في كل الأوراق. لا تغيّر نصوص الحالات (مسودة/معتمد/مرحل/معكوس/ملغى) لأن المعادلات تعتمد عليها.
A4: حالة المستند | B4: Code | C4: المعنى | E4: نوع السند | F4: Code | G4: بادئة الرقم | H4: الوصف | J4: نوع فاتورة المورد | K4: Code | L4: الوصف | N4: نمط سداد المصروف | O4: Code | P4: الوصف | R4: نعم/لا | T4: فئة الإيراد | U4: حساب الإيراد | W4: نوع القيد اليدوي | Y4: سبب الفرق | AA4: حالة المعالجة | AC4: تصنيف التدفق | AD4: المعنى | AF4: نوع الخزينة | AH4: نوع الموقع | AJ4: رمز النوع | AK4: نوع الحساب | AM4: نوع وسيلة الدفع | AO4: الأدوار
A5: مسودة | B5: DRAFT | C5: مستند مُعد ولم يُعتمد بعد - لا يؤثر على الدفاتر | E5: قبض | F5: RCV | G5: RCV | H5: سند قبض نقدية/بنك من جهة (حساب مقابل دائن) | J5: فاتورة | K5: INV | L5: فاتورة مورد | N5: فوري | O5: IMM | P5: مدفوع وقت الإثبات | R5: نعم | T5: فطير | U5: 4101 | W5: افتتاحي | Y5: خطأ إدخال | AA5: تمت التسوية | AC5: OPERATING | AD5: تشغيلية | AF5: خزينة | AH5: فرع | AJ5: A | AK5: أصل | AM5: نقدي | AO5: الإدارة العليا
A6: معتمد | B6: APPROVED | C6: اعتمده المسؤول ولم يرحّله المحاسب بعد - لا يؤثر على الدفاتر | E6: صرف | F6: PAY | G6: PAY | H6: سند صرف نقدية/بنك لجهة (حساب مقابل مدين) | J6: إشعار خصم (مرتجع) | K6: CN | L6: تخفيض مديونية المورد | N6: آجل | O6: CRD | P6: مستحق ويُسدد لاحقًا بسند صرف مرتبط | R6: لا | T6: بيتزا | U6: 4102 | W6: تسوية | Y6: عجز نقدي | AA6: معلق | AC6: INVESTING | AD6: استثمارية | AF6: بنك | AH6: مخزن رئيسي | AJ6: L | AK6: التزام | AM6: بطاقة | AO6: المدير المالي
A7: مرحل | B7: POSTED | C7: رحّله المحاسب - يؤثر على دفتر اليومية والأستاذ | E7: تحويل بين خزائن | F7: TRF | G7: TRF | H7: نقل نقدية بين خزينتين - لا يؤثر على الإيراد/المصروف | J7: إشعار إضافة | K7: DN | L7: زيادة مديونية المورد (رسوم/فروق سعر) | T7: مكرونات | U7: 4103 | W7: تصحيح | Y7: زيادة نقدية | AA7: مقبول بموافقة الإدارة | AC7: FINANCING | AD7: تمويلية | AF7: عهدة نثرية | AH7: سنتر كيتشن | AJ7: E | AK7: حقوق ملكية | AM7: منصة | AO7: المحاسب
A8: معكوس | B8: REVERSED | C8: أُلغي أثره بمستند تصحيح موثق (مرجع التصحيح إلزامي) | E8: إيداع بنكي | F8: DEP | G8: TRF | H8: من خزينة إلى بنك | T8: أخرى | U8: 4104 | W8: عكس | Y8: تأخر تحصيل | AC8: INTERNAL | AD8: تحويل داخلي (يجب أن يصفّر) | AH8: إدارة | AJ8: R | AK8: إيراد | AM8: تحويل | AO8: مراجع الحسابات
A9: ملغى | B9: CANCELLED | C9: ألغي قبل الترحيل - يبقى في السجل ولا يؤثر | E9: سحب بنكي | F9: WDR | G9: TRF | H9: من بنك إلى خزينة | W9: إهلاك | Y9: خصم غير مسجل | AC9: OPENING | AD9: رصيد افتتاحي | AJ9: C | AK9: تكلفة مبيعات | AO9: مدير فرع
E10: عجز خزينة | F10: SHT | G10: ADJ | H10: فرق جرد خزينة بالنقص | W10: تسوية تكلفة المبيعات | Y10: إلغاء بعد الدفع | AJ10: X | AK10: مصروف | AO10: أمين صندوق
E11: زيادة خزينة | F11: OVR | G11: ADJ | H11: فرق جرد خزينة بالزيادة | W11: استحقاق/مقدم | Y11: فرق عمولة منصة | AO11: أمين مخزن
W12: رواتب (مؤقت) | Y12: مستند ناقص | AO12: مشرف مشتريات
W13: إقفال | Y13: أخرى | AO13: مدير إنتاج
W14: أخرى | AO14: مستخدم قراءة

Sheet COA
A1: دليل الحسابات الموحد (Chart of Accounts)
A2: ترقيم 4 خانات: الفئة (1-6) ثم المجموعة (100) ثم الحساب. أضف حسابًا جديدًا في أي صف فارغ بالنطاق المناسب ويظهر فورًا في ميزان المراجعة. الحسابات الرئيسية (لا) لا يُرحَّل عليها.
A3: خلايا الإدخال | B3: معادلات (لا تعدّل)
A4: كود الحساب Code | B4: اسم الحساب Name (AR) | C4: Account Name (EN) | D4: النوع | E4: المستوى | F4: قابل للترحيل | G4: الطبيعة | H4: نقدية/بنك (1/0) | I4: تصنيف التدفق | J4: مسموح في المصروفات | K4: مسموح في المشتريات | L4: نشط | M4: من نطاق (للرئيسي) | N4: إلى نطاق (للرئيسي) | O4: ملاحظات | P4: بداية النطاق | Q4: نهاية النطاق | R4: صالح للترحيل (1/0) | S4: نوع الحساب | T4: فحص
A5: 1000 | B5: الأصول | C5: Assets | D5: A | E5: 1 | F5: لا | G5: مدين | H5: 0 | I5: OPERATING | J5: لا | K5: لا | L5: نعم | M5: 1000 | N5: 1999 | P5: =IF($A5="","",IF($F5="نعم",$A5,$M5)) | Q5: =IF($A5="","",IF($F5="نعم",$A5,$N5)) | R5: =IF($A5="","",IF(AND($F5="نعم",$L5<>"لا"),1,0)) | S5: =IF($D5="","",IFERROR(INDEX(Lists!$AK$5:$AK$10,MATCH($D5,Lists!$AJ$5:$AJ$10,0)),"نوع غير معرف")) | T5: =IF($A5="","",IF(COUNTIF($A:$A,$A5)>1,"كود حساب مكرر",IF($B5="","اسم الحساب ناقص",IF(AND($F5="نعم",$G5=""),"الطبيعة ناقصة",IF(AND($F5<>"نعم",OR($M5="",$N5="")),"الحساب الرئيسي يحتاج نطاقًا (من/إلى)",IF(AND($H5=1,$F5<>"نعم"),"حساب نقدية يجب أن يكون قابلًا للترحيل",IF(AND($F5="نعم",$D5=""),"النوع ناقص","")))))))
A6: 1100 | B6: النقدية والخزائن | C6: Cash on Hand | D6: A | E6: 2 | F6: لا | G6: مدين | H6: 0 | I6: OPERATING | J6: لا | K6: لا | L6: نعم | M6: 1100 | N6: 1199 | P6: =IF($A6="","",IF($F6="نعم",$A6,$M6)) | Q6: =IF($A6="","",IF($F6="نعم",$A6,$N6)) | R6: =IF($A6="","",IF(AND($F6="نعم",$L6<>"لا"),1,0)) | S6: =IF($D6="","",IFERROR(INDEX(Lists!$AK$5:$AK$10,MATCH($D6,Lists!$AJ$5:$AJ$10,0)),"نوع غير معرف")) | T6: =IF($A6="","",IF(COUNTIF($A:$A,$A6)>1,"كود حساب مكرر",IF($B6="","اسم الحساب ناقص",IF(AND($F6="نعم",$G6=""),"الطبيعة ناقصة",IF(AND($F6<>"نعم",OR($M6="",$N6="")),"الحساب الرئيسي يحتاج نطاقًا (من/إلى)",IF(AND($H6=1,$F6<>"نعم"),"حساب نقدية يجب أن يكون قابلًا للترحيل",IF(AND($F6="نعم",$D6=""),"النوع ناقص","")))))))
A7: 1101 | B7: خزينة الفرع BR01 | C7: Cash - Branch BR01 | D7: A | E7: 3 | F7: نعم | G7: مدين | H7: 1 | I7: OPERATING | J7: لا | K7: لا | L7: نعم | P7: =IF($A7="","",IF($F7="نعم",$A7,$M7)) | Q7: =IF($A7="","",IF($F7="نعم",$A7,$N7)) | R7: =IF($A7="","",IF(AND($F7="نعم",$L7<>"لا"),1,0)) | S7: =IF($D7="","",IFERROR(INDEX(Lists!$AK$5:$AK$10,MATCH($D7,Lists!$AJ$5:$AJ$10,0)),"نوع غير معرف")) | T7: =IF($A7="","",IF(COUNTIF($A:$A,$A7)>1,"كود حساب مكرر",IF($B7="","اسم الحساب ناقص",IF(AND($F7="نعم",$G7=""),"الطبيعة ناقصة",IF(AND($F7<>"نعم",OR($M7="",$N7="")),"الحساب الرئيسي يحتاج نطاقًا (من/إلى)",IF(AND($H7=1,$F7<>"نعم"),"حساب نقدية يجب أن يكون قابلًا للترحيل",IF(AND($F7="نعم",$D7=""),"النوع ناقص","")))))))
A8: 1102 | B8: خزينة الفرع BR02 | C8: Cash - Branch BR02 | D8: A | E8: 3 | F8: نعم | G8: مدين | H8: 1 | I8: OPERATING | J8: لا | K8: لا | L8: نعم | P8: =IF($A8="","",IF($F8="نعم",$A8,$M8)) | Q8: =IF($A8="","",IF($F8="نعم",$A8,$N8)) | R8: =IF($A8="","",IF(AND($F8="نعم",$L8<>"لا"),1,0)) | S8: =IF($D8="","",IFERROR(INDEX(Lists!$AK$5:$AK$10,MATCH($D8,Lists!$AJ$5:$AJ$10,0)),"نوع غير معرف")) | T8: =IF($A8="","",IF(COUNTIF($A:$A,$A8)>1,"كود حساب مكرر",IF($B8="","اسم الحساب ناقص",IF(AND($F8="نعم",$G8=""),"الطبيعة ناقصة",IF(AND($F8<>"نعم",OR($M8="",$N8="")),"الحساب الرئيسي يحتاج نطاقًا (من/إلى)",IF(AND($H8=1,$F8<>"نعم"),"حساب نقدية يجب أن يكون قابلًا للترحيل",IF(AND($F8="نعم",$D8=""),"النوع ناقص","")))))))
A9: 1103 | B9: خزينة الفرع BR03 | C9: Cash - Branch BR03 | D9: A | E9: 3 | F9: نعم | G9: مدين | H9: 1 | I9: OPERATING | J9: لا | K9: لا | L9: نعم | P9: =IF($A9="","",IF($F9="نعم",$A9,$M9)) | Q9: =IF($A9="","",IF($F9="نعم",$A9,$N9)) | R9: =IF($A9="","",IF(AND($F9="نعم",$L9<>"لا"),1,0)) | S9: =IF($D9="","",IFERROR(INDEX(Lists!$AK$5:$AK$10,MATCH($D9,Lists!$AJ$5:$AJ$10,0)),"نوع غير معرف")) | T9: =IF($A9="","",IF(COUNTIF($A:$A,$A9)>1,"كود حساب مكرر",IF($B9="","اسم الحساب ناقص",IF(AND($F9="نعم",$G9=""),"الطبيعة ناقصة",IF(AND($F9<>"نعم",OR($M9="",$N9="")),"الحساب الرئيسي يحتاج نطاقًا (من/إلى)",IF(AND($H9=1,$F9<>"نعم"),"حساب نقدية يجب أن يكون قابلًا للترحيل",IF(AND($F9="نعم",$D9=""),"النوع ناقص","")))))))
A10: 1104 | B10: خزينة الإدارة الرئيسية HQ01 | C10: Cash - Head Office | D10: A | E10: 3 | F10: نعم | G10: مدين | H10: 1 | I10: OPERATING | J10: لا | K10: لا | L10: نعم | P10: =IF($A10="","",IF($F10="نعم",$A10,$M10)) | Q10: =IF($A10="","",IF($F10="نعم",$A10,$N10)) | R10: =IF($A10="","",IF(AND($F10="نعم",$L10<>"لا"),1,0)) | S10: =IF($D10="","",IFERROR(INDEX(Lists!$AK$5:$AK$10,MATCH($D10,Lists!$AJ$5:$AJ$10,0)),"نوع غير معرف")) | T10: =IF($A10="","",IF(COUNTIF($A:$A,$A10)>1,"كود حساب مكرر",IF($B10="","اسم الحساب ناقص",IF(AND($F10="نعم",$G10=""),"الطبيعة ناقصة",IF(AND($F10<>"نعم",OR($M10="",$N10="")),"الحساب الرئيسي يحتاج نطاقًا (من/إلى)",IF(AND($H10=1,$F10<>"نعم"),"حساب نقدية يجب أن يكون قابلًا للترحيل",IF(AND($F10="نعم",$D10=""),"النوع ناقص","")))))))
A11: 1105 | B11: عهدة المصروفات النثرية | C11: Petty Cash | D11: A | E11: 3 | F11: نعم | G11: مدين | H11: 1 | I11: OPERATING | J11: لا | K11: لا | L11: نعم | P11: =IF($A11="","",IF($F11="نعم",$A11,$M11)) | Q11: =IF($A11="","",IF($F11="نعم",$A11,$N11)) | R11: =IF($A11="","",IF(AND($F11="نعم",$L11<>"لا"),1,0)) | S11: =IF($D11="","",IFERROR(INDEX(Lists!$AK$5:$AK$10,MATCH($D11,Lists!$AJ$5:$AJ$10,0)),"نوع غير معرف")) | T11: =IF($A11="","",IF(COUNTIF($A:$A,$A11)>1,"كود حساب مكرر",IF($B11="","اسم الحساب ناقص",IF(AND($F11="نعم",$G11=""),"الطبيعة ناقصة",IF(AND($F11<>"نعم",OR($M11="",$N11="")),"الحساب الرئيسي يحتاج نطاقًا (من/إلى)",IF(AND($H11=1,$F11<>"نعم"),"حساب نقدية يجب أن يكون قابلًا للترحيل",IF(AND($F11="نعم",$D11=""),"النوع ناقص","")))))))
A12: 1106 | B12: نقدية بالطريق (تحويلات قيد التسوية) | C12: Cash in Transit | D12: A | E12: 3 | F12: نعم | G12: مدين | H12: 1 | I12: OPERATING | J12: لا | K12: لا | L12: نعم | O12: يجب أن يكون رصيده صفرًا عند الإقفال | P12: =IF($A12="","",IF($F12="نعم",$A12,$M12)) | Q12: =IF($A12="","",IF($F12="نعم",$A12,$N12)) | R12: =IF($A12="","",IF(AND($F12="نعم",$L12<>"لا"),1,0)) | S12: =IF($D12="","",IFERROR(INDEX(Lists!$AK$5:$AK$10,MATCH($D12,Lists!$AJ$5:$AJ$10,0)),"نوع غير معرف")) | T12: =IF($A12="","",IF(COUNTIF($A:$A,$A12)>1,"كود حساب مكرر",IF($B12="","اسم الحساب ناقص",IF(AND($F12="نعم",$G12=""),"الطبيعة ناقصة",IF(AND($F12<>"نعم",OR($M12="",$N12="")),"الحساب الرئيسي يحتاج نطاقًا (من/إلى)",IF(AND($H12=1,$F12<>"نعم"),"حساب نقدية يجب أن يكون قابلًا للترحيل",IF(AND($F12="نعم",$D12=""),"النوع ناقص","")))))))
A13: 1200 | B13: البنوك | C13: Banks | D13: A | E13: 2 | F13: لا | G13: مدين | H13: 0 | I13: OPERATING | J13: لا | K13: لا | L13: نعم | M13: 1200 | N13: 1299 | P13: =IF($A13="","",IF($F13="نعم",$A13,$M13)) | Q13: =IF($A13="","",IF($F13="نعم",$A13,$N13)) | R13: =IF($A13="","",IF(AND($F13="نعم",$L13<>"لا"),1,0)) | S13: =IF($D13="","",IFERROR(INDEX(Lists!$AK$5:$AK$10,MATCH($D13,Lists!$AJ$5:$AJ$10,0)),"نوع غير معرف")) | T13: =IF($A13="","",IF(COUNTIF($A:$A,$A13)>1,"كود حساب مكرر",IF($B13="","اسم الحساب ناقص",IF(AND($F13="نعم",$G13=""),"الطبيعة ناقصة",IF(AND($F13<>"نعم",OR($M13="",$N13="")),"الحساب الرئيسي يحتاج نطاقًا (من/إلى)",IF(AND($H13=1,$F13<>"نعم"),"حساب نقدية يجب أن يكون قابلًا للترحيل",IF(AND($F13="نعم",$D13=""),"النوع ناقص","")))))))
A14: 1201 | B14: البنك الأول - حساب جاري (تجريبي) | C14: Bank 1 - Current | D14: A | E14: 3 | F14: نعم | G14: مدين | H14: 1 | I14: OPERATING | J14: لا | K14: لا | L14: نعم | P14: =IF($A14="","",IF($F14="نعم",$A14,$M14)) | Q14: =IF($A14="","",IF($F14="نعم",$A14,$N14)) | R14: =IF($A14="","",IF(AND($F14="نعم",$L14<>"لا"),1,0)) | S14: =IF($D14="","",IFERROR(INDEX(Lists!$AK$5:$AK$10,MATCH($D14,Lists!$AJ$5:$AJ$10,0)),"نوع غير معرف")) | T14: =IF($A14="","",IF(COUNTIF($A:$A,$A14)>1,"كود حساب مكرر",IF($B14="","اسم الحساب ناقص",IF(AND($F14="نعم",$G14=""),"الطبيعة ناقصة",IF(AND($F14<>"نعم",OR($M14="",$N14="")),"الحساب الرئيسي يحتاج نطاقًا (من/إلى)",IF(AND($H14=1,$F14<>"نعم"),"حساب نقدية يجب أن يكون قابلًا للترحيل",IF(AND($F14="نعم",$D14=""),"النوع ناقص","")))))))
A15: 1202 | B15: البنك الثاني - حساب جاري (تجريبي) | C15: Bank 2 - Current | D15: A | E15: 3 | F15: نعم | G15: مدين | H15: 1 | I15: OPERATING | J15: لا | K15: لا | L15: نعم | P15: =IF($A15="","",IF($F15="نعم",$A15,$M15)) | Q15: =IF($A15="","",IF($F15="نعم",$A15,$N15)) | R15: =IF($A15="","",IF(AND($F15="نعم",$L15<>"لا"),1,0)) | S15: =IF($D15="","",IFERROR(INDEX(Lists!$AK$5:$AK$10,MATCH($D15,Lists!$AJ$5:$AJ$10,0)),"نوع غير معرف")) | T15: =IF($A15="","",IF(COUNTIF($A:$A,$A15)>1,"كود حساب مكرر",IF($B15="","اسم الحساب ناقص",IF(AND($F15="نعم",$G15=""),"الطبيعة ناقصة",IF(AND($F15<>"نعم",OR($M15="",$N15="")),"الحساب الرئيسي يحتاج نطاقًا (من/إلى)",IF(AND($H15=1,$F15<>"نعم"),"حساب نقدية يجب أن يكون قابلًا للترحيل",IF(AND($F15="نعم",$D15=""),"النوع ناقص","")))))))
A16: 1203 | B16: محافظ وتحويلات إلكترونية | C16: E-wallets / Instant transfers | D16: A | E16: 3 | F16: نعم | G16: مدين | H16: 1 | I16: OPERATING | J16: لا | K16: لا | L16: نعم | P16: =IF($A16="","",IF($F16="نعم",$A16,$M16)) | Q16: =IF($A16="","",IF($F16="نعم",$A16,$N16)) | R16: =IF($A16="","",IF(AND($F16="نعم",$L16<>"لا"),1,0)) | S16: =IF($D16="","",IFERROR(INDEX(Lists!$AK$5:$AK$10,MATCH($D16,Lists!$AJ$5:$AJ$10,0)),"نوع غير معرف")) | T16: =IF($A16="","",IF(COUNTIF($A:$A,$A16)>1,"كود حساب مكرر",IF($B16="","اسم الحساب ناقص",IF(AND($F16="نعم",$G16=""),"الطبيعة ناقصة",IF(AND($F16<>"نعم",OR($M16="",$N16="")),"الحساب الرئيسي يحتاج نطاقًا (من/إلى)",IF(AND($H16=1,$F16<>"نعم"),"حساب نقدية يجب أن يكون قابلًا للترحيل",IF(AND($F16="نعم",$D16=""),"النوع ناقص","")))))))
A17: 1300 | B17: العملاء ومنصات التوصيل والبطاقات | C17: Receivables & Platforms | D17: A | E17: 2 | F17: لا | G17: مدين | H17: 0 | I17: OPERATING | J17: لا | K17: لا | L17: نعم | M17: 1300 | N17: 1399 | P17: =IF($A17="","",IF($F17="نعم",$A17,$M17)) | Q17: =IF($A17="","",IF($F17="نعم",$A17,$N17)) | R17: =IF($A17="","",IF(AND($F17="نعم",$L17<>"لا"),1,0)) | S17: =IF($D17="","",IFERROR(INDEX(Lists!$AK$5:$AK$10,MATCH($D17,Lists!$AJ$5:$AJ$10,0)),"نوع غير معرف")) | T17: =IF($A17="","",IF(COUNTIF($A:$A,$A17)>1,"كود حساب مكرر",IF($B17="","اسم الحساب ناقص",IF(AND($F17="نعم",$G17=""),"الطبيعة ناقصة",IF(AND($F17<>"نعم",OR($M17="",$N17="")),"الحساب الرئيسي يحتاج نطاقًا (من/إلى)",IF(AND($H17=1,$F17<>"نعم"),"حساب نقدية يجب أن يكون قابلًا للترحيل",IF(AND($F17="نعم",$D17=""),"النوع ناقص","")))))))
A18: 1301 | B18: عملاء (مدينون تجاريون) | C18: Trade Receivables | D18: A | E18: 3 | F18: نعم | G18: مدين | H18: 0 | I18: OPERATING | J18: لا | K18: لا | L18: نعم | P18: =IF($A18="","",IF($F18="نعم",$A18,$M18)) | Q18: =IF($A18="","",IF($F18="نعم",$A18,$N18)) | R18: =IF($A18="","",IF(AND($F18="نعم",$L18<>"لا"),1,0)) | S18: =IF($D18="","",IFERROR(INDEX(Lists!$AK$5:$AK$10,MATCH($D18,Lists!$AJ$5:$AJ$10,0)),"نوع غير معرف")) | T18: =IF($A18="","",IF(COUNTIF($A:$A,$A18)>1,"كود حساب مكرر",IF($B18="","اسم الحساب ناقص",IF(AND($F18="نعم",$G18=""),"الطبيعة ناقصة",IF(AND($F18<>"نعم",OR($M18="",$N18="")),"الحساب الرئيسي يحتاج نطاقًا (من/إلى)",IF(AND($H18=1,$F18<>"نعم"),"حساب نقدية يجب أن يكون قابلًا للترحيل",IF(AND($F18="نعم",$D18=""),"النوع ناقص","")))))))
A19: 1302 | B19: مستحقات بطاقات الدفع (POS Clearing) | C19: Card Settlements Receivable | D19: A | E19: 3 | F19: نعم | G19: مدين | H19: 0 | I19: OPERATING | J19: لا | K19: لا | L19: نعم | P19: =IF($A19="","",IF($F19="نعم",$A19,$M19)) | Q19: =IF($A19="","",IF($F19="نعم",$A19,$N19)) | R19: =IF($A19="","",IF(AND($F19="نعم",$L19<>"لا"),1,0)) | S19: =IF($D19="","",IFERROR(INDEX(Lists!$AK$5:$AK$10,MATCH($D19,Lists!$AJ$5:$AJ$10,0)),"نوع غير معرف")) | T19: =IF($A19="","",IF(COUNTIF($A:$A,$A19)>1,"كود حساب مكرر",IF($B19="","اسم الحساب ناقص",IF(AND($F19="نعم",$G19=""),"الطبيعة ناقصة",IF(AND($F19<>"نعم",OR($M19="",$N19="")),"الحساب الرئيسي يحتاج نطاقًا (من/إلى)",IF(AND($H19=1,$F19<>"نعم"),"حساب نقدية يجب أن يكون قابلًا للترحيل",IF(AND($F19="نعم",$D19=""),"النوع ناقص","")))))))
A20: 1303 | B20: مستحقات منصة طلبات | C20: Receivable - Talabat | D20: A | E20: 3 | F20: نعم | G20: مدين | H20: 0 | I20: OPERATING | J20: لا | K20: لا | L20: نعم | P20: =IF($A20="","",IF($F20="نعم",$A20,$M20)) | Q20: =IF($A20="","",IF($F20="نعم",$A20,$N20)) | R20: =IF($A20="","",IF(AND($F20="نعم",$L20<>"لا"),1,0)) | S20: =IF($D20="","",IFERROR(INDEX(Lists!$AK$5:$AK$10,MATCH($D20,Lists!$AJ$5:$AJ$10,0)),"نوع غير معرف")) | T20: =IF($A20="","",IF(COUNTIF($A:$A,$A20)>1,"كود حساب مكرر",IF($B20="","اسم الحساب ناقص",IF(AND($F20="نعم",$G20=""),"الطبيعة ناقصة",IF(AND($F20<>"نعم",OR($M20="",$N20="")),"الحساب الرئيسي يحتاج نطاقًا (من/إلى)",IF(AND($H20=1,$F20<>"نعم"),"حساب نقدية يجب أن يكون قابلًا للترحيل",IF(AND($F20="نعم",$D20=""),"النوع ناقص","")))))))
A21: 1304 | B21: مستحقات منصة توصيل أخرى | C21: Receivable - Other Delivery Platform | D21: A | E21: 3 | F21: نعم | G21: مدين | H21: 0 | I21: OPERATING | J21: لا | K21: لا | L21: نعم | P21: =IF($A21="","",IF($F21="نعم",$A21,$M21)) | Q21: =IF($A21="","",IF($F21="نعم",$A21,$N21)) | R21: =IF($A21="","",IF(AND($F21="نعم",$L21<>"لا"),1,0)) | S21: =IF($D21="","",IFERROR(INDEX(Lists!$AK$5:$AK$10,MATCH($D21,Lists!$AJ$5:$AJ$10,0)),"نوع غير معرف")) | T21: =IF($A21="","",IF(COUNTIF($A:$A,$A21)>1,"كود حساب مكرر",IF($B21="","اسم الحساب ناقص",IF(AND($F21="نعم",$G21=""),"الطبيعة ناقصة",IF(AND($F21<>"نعم",OR($M21="",$N21="")),"الحساب الرئيسي يحتاج نطاقًا (من/إلى)",IF(AND($H21=1,$F21<>"نعم"),"حساب نقدية يجب أن يكون قابلًا للترحيل",IF(AND($F21="نعم",$D21=""),"النوع ناقص","")))))))
A22: 1309 | B22: فروق تسوية المنصات تحت المراجعة | C22: Platform Settlement Differences (pending) | D22: A | E22: 3 | F22: نعم | G22: مدين | H22: 0 | I22: OPERATING | J22: لا | K22: لا | L22: نعم | O22: حساب مراجعة؛ يُسوّى شهريًا | P22: =IF($A22="","",IF($F22="نعم",$A22,$M22)) | Q22: =IF($A22="","",IF($F22="نعم",$A22,$N22)) | R22: =IF($A22="","",IF(AND($F22="نعم",$L22<>"لا"),1,0)) | S22: =IF($D22="","",IFERROR(INDEX(Lists!$AK$5:$AK$10,MATCH($D22,Lists!$AJ$5:$AJ$10,0)),"نوع غير معرف")) | T22: =IF($A22="","",IF(COUNTIF($A:$A,$A22)>1,"كود حساب مكرر",IF($B22="","اسم الحساب ناقص",IF(AND($F22="نعم",$G22=""),"الطبيعة ناقصة",IF(AND($F22<>"نعم",OR($M22="",$N22="")),"الحساب الرئيسي يحتاج نطاقًا (من/إلى)",IF(AND($H22=1,$F22<>"نعم"),"حساب نقدية يجب أن يكون قابلًا للترحيل",IF(AND($F22="نعم",$D22=""),"النوع ناقص","")))))))
A23: 1400 | B23: المخزون | C23: Inventory | D23: A | E23: 2 | F23: لا | G23: مدين | H23: 0 | I23: OPERATING | J23: لا | K23: لا | L23: نعم | M23: 1400 | N23: 1499 | P23: =IF($A23="","",IF($F23="نعم",$A23,$M23)) | Q23: =IF($A23="","",IF($F23="نعم",$A23,$N23)) | R23: =IF($A23="","",IF(AND($F23="نعم",$L23<>"لا"),1,0)) | S23: =IF($D23="","",IFERROR(INDEX(Lists!$AK$5:$AK$10,MATCH($D23,Lists!$AJ$5:$AJ$10,0)),"نوع غير معرف")) | T23: =IF($A23="","",IF(COUNTIF($A:$A,$A23)>1,"كود حساب مكرر",IF($B23="","اسم الحساب ناقص",IF(AND($F23="نعم",$G23=""),"الطبيعة ناقصة",IF(AND($F23<>"نعم",OR($M23="",$N23="")),"الحساب الرئيسي يحتاج نطاقًا (من/إلى)",IF(AND($H23=1,$F23<>"نعم"),"حساب نقدية يجب أن يكون قابلًا للترحيل",IF(AND($F23="نعم",$D23=""),"النوع ناقص","")))))))
A24: 1401 | B24: مخزون المخزن الرئيسي - مواد خام | C24: Inventory - Main Warehouse (raw) | D24: A | E24: 3 | F24: نعم | G24: مدين | H24: 0 | I24: OPERATING | J24: لا | K24: نعم | L24: نعم | P24: =IF($A24="","",IF($F24="نعم",$A24,$M24)) | Q24: =IF($A24="","",IF($F24="نعم",$A24,$N24)) | R24: =IF($A24="","",IF(AND($F24="نعم",$L24<>"لا"),1,0)) | S24: =IF($D24="","",IFERROR(INDEX(Lists!$AK$5:$AK$10,MATCH($D24,Lists!$AJ$5:$AJ$10,0)),"نوع غير معرف")) | T24: =IF($A24="","",IF(COUNTIF($A:$A,$A24)>1,"كود حساب مكرر",IF($B24="","اسم الحساب ناقص",IF(AND($F24="نعم",$G24=""),"الطبيعة ناقصة",IF(AND($F24<>"نعم",OR($M24="",$N24="")),"الحساب الرئيسي يحتاج نطاقًا (من/إلى)",IF(AND($H24=1,$F24<>"نعم"),"حساب نقدية يجب أن يكون قابلًا للترحيل",IF(AND($F24="نعم",$D24=""),"النوع ناقص","")))))))
A25: 1402 | B25: مخزون السنتر كيتشن - مواد خام | C25: Inventory - Central Kitchen (raw) | D25: A | E25: 3 | F25: نعم | G25: مدين | H25: 0 | I25: OPERATING | J25: لا | K25: نعم | L25: نعم | P25: =IF($A25="","",IF($F25="نعم",$A25,$M25)) | Q25: =IF($A25="","",IF($F25="نعم",$A25,$N25)) | R25: =IF($A25="","",IF(AND($F25="نعم",$L25<>"لا"),1,0)) | S25: =IF($D25="","",IFERROR(INDEX(Lists!$AK$5:$AK$10,MATCH($D25,Lists!$AJ$5:$AJ$10,0)),"نوع غير معرف")) | T25: =IF($A25="","",IF(COUNTIF($A:$A,$A25)>1,"كود حساب مكرر",IF($B25="","اسم الحساب ناقص",IF(AND($F25="نعم",$G25=""),"الطبيعة ناقصة",IF(AND($F25<>"نعم",OR($M25="",$N25="")),"الحساب الرئيسي يحتاج نطاقًا (من/إلى)",IF(AND($H25=1,$F25<>"نعم"),"حساب نقدية يجب أن يكون قابلًا للترحيل",IF(AND($F25="نعم",$D25=""),"النوع ناقص","")))))))
A26: 1403 | B26: مخزون منتجات نصف مصنعة وتامة | C26: Inventory - WIP/Finished Goods | D26: A | E26: 3 | F26: نعم | G26: مدين | H26: 0 | I26: OPERATING | J26: لا | K26: نعم | L26: نعم | P26: =IF($A26="","",IF($F26="نعم",$A26,$M26)) | Q26: =IF($A26="","",IF($F26="نعم",$A26,$N26)) | R26: =IF($A26="","",IF(AND($F26="نعم",$L26<>"لا"),1,0)) | S26: =IF($D26="","",IFERROR(INDEX(Lists!$AK$5:$AK$10,MATCH($D26,Lists!$AJ$5:$AJ$10,0)),"نوع غير معرف")) | T26: =IF($A26="","",IF(COUNTIF($A:$A,$A26)>1,"كود حساب مكرر",IF($B26="","اسم الحساب ناقص",IF(AND($F26="نعم",$G26=""),"الطبيعة ناقصة",IF(AND($F26<>"نعم",OR($M26="",$N26="")),"الحساب الرئيسي يحتاج نطاقًا (من/إلى)",IF(AND($H26=1,$F26<>"نعم"),"حساب نقدية يجب أن يكون قابلًا للترحيل",IF(AND($F26="نعم",$D26=""),"النوع ناقص","")))))))
A27: 1404 | B27: مخزون الفروع | C27: Inventory - Branches | D27: A | E27: 3 | F27: نعم | G27: مدين | H27: 0 | I27: OPERATING | J27: لا | K27: نعم | L27: نعم | P27: =IF($A27="","",IF($F27="نعم",$A27,$M27)) | Q27: =IF($A27="","",IF($F27="نعم",$A27,$N27)) | R27: =IF($A27="","",IF(AND($F27="نعم",$L27<>"لا"),1,0)) | S27: =IF($D27="","",IFERROR(INDEX(Lists!$AK$5:$AK$10,MATCH($D27,Lists!$AJ$5:$AJ$10,0)),"نوع غير معرف")) | T27: =IF($A27="","",IF(COUNTIF($A:$A,$A27)>1,"كود حساب مكرر",IF($B27="","اسم الحساب ناقص",IF(AND($F27="نعم",$G27=""),"الطبيعة ناقصة",IF(AND($F27<>"نعم",OR($M27="",$N27="")),"الحساب الرئيسي يحتاج نطاقًا (من/إلى)",IF(AND($H27=1,$F27<>"نعم"),"حساب نقدية يجب أن يكون قابلًا للترحيل",IF(AND($F27="نعم",$D27=""),"النوع ناقص","")))))))
A28: 1405 | B28: مخزون عبوات وتغليف | C28: Inventory - Packaging | D28: A | E28: 3 | F28: نعم | G28: مدين | H28: 0 | I28: OPERATING | J28: لا | K28: نعم | L28: نعم | P28: =IF($A28="","",IF($F28="نعم",$A28,$M28)) | Q28: =IF($A28="","",IF($F28="نعم",$A28,$N28)) | R28: =IF($A28="","",IF(AND($F28="نعم",$L28<>"لا"),1,0)) | S28: =IF($D28="","",IFERROR(INDEX(Lists!$AK$5:$AK$10,MATCH($D28,Lists!$AJ$5:$AJ$10,0)),"نوع غير معرف")) | T28: =IF($A28="","",IF(COUNTIF($A:$A,$A28)>1,"كود حساب مكرر",IF($B28="","اسم الحساب ناقص",IF(AND($F28="نعم",$G28=""),"الطبيعة ناقصة",IF(AND($F28<>"نعم",OR($M28="",$N28="")),"الحساب الرئيسي يحتاج نطاقًا (من/إلى)",IF(AND($H28=1,$F28<>"نعم"),"حساب نقدية يجب أن يكون قابلًا للترحيل",IF(AND($F28="نعم",$D28=""),"النوع ناقص","")))))))
A29: 1406 | B29: إنتاج تحت التشغيل (WIP) | C29: Work in Process | D29: A | E29: 3 | F29: نعم | G29: مدين | H29: 0 | I29: OPERATING | J29: لا | K29: لا | L29: نعم | O29: المرحلة 2 | P29: =IF($A29="","",IF($F29="نعم",$A29,$M29)) | Q29: =IF($A29="","",IF($F29="نعم",$A29,$N29)) | R29: =IF($A29="","",IF(AND($F29="نعم",$L29<>"لا"),1,0)) | S29: =IF($D29="","",IFERROR(INDEX(Lists!$AK$5:$AK$10,MATCH($D29,Lists!$AJ$5:$AJ$10,0)),"نوع غير معرف")) | T29: =IF($A29="","",IF(COUNTIF($A:$A,$A29)>1,"كود حساب مكرر",IF($B29="","اسم الحساب ناقص",IF(AND($F29="نعم",$G29=""),"الطبيعة ناقصة",IF(AND($F29<>"نعم",OR($M29="",$N29="")),"الحساب الرئيسي يحتاج نطاقًا (من/إلى)",IF(AND($H29=1,$F29<>"نعم"),"حساب نقدية يجب أن يكون قابلًا للترحيل",IF(AND($F29="نعم",$D29=""),"النوع ناقص","")))))))
A30: 1407 | B30: بضاعة بالطريق (تحويلات مخزنية مفتوحة) | C30: Goods in Transit | D30: A | E30: 3 | F30: نعم | G30: مدين | H30: 0 | I30: OPERATING | J30: لا | K30: لا | L30: نعم | O30: المرحلة 2 | P30: =IF($A30="","",IF($F30="نعم",$A30,$M30)) | Q30: =IF($A30="","",IF($F30="نعم",$A30,$N30)) | R30: =IF($A30="","",IF(AND($F30="نعم",$L30<>"لا"),1,0)) | S30: =IF($D30="","",IFERROR(INDEX(Lists!$AK$5:$AK$10,MATCH($D30,Lists!$AJ$5:$AJ$10,0)),"نوع غير معرف")) | T30: =IF($A30="","",IF(COUNTIF($A:$A,$A30)>1,"كود حساب مكرر",IF($B30="","اسم الحساب ناقص",IF(AND($F30="نعم",$G30=""),"الطبيعة ناقصة",IF(AND($F30<>"نعم",OR($M30="",$N30="")),"الحساب الرئيسي يحتاج نطاقًا (من/إلى)",IF(AND($H30=1,$F30<>"نعم"),"حساب نقدية يجب أن يكون قابلًا للترحيل",IF(AND($F30="نعم",$D30=""),"النوع ناقص","")))))))
A31: 1500 | B31: السلف والعهد | C31: Advances & Custody | D31: A | E31: 2 | F31: لا | G31: مدين | H31: 0 | I31: OPERATING | J31: لا | K31: لا | L31: نعم | M31: 1500 | N31: 1599 | P31: =IF($A31="","",IF($F31="نعم",$A31,$M31)) | Q31: =IF($A31="","",IF($F31="نعم",$A31,$N31)) | R31: =IF($A31="","",IF(AND($F31="نعم",$L31<>"لا"),1,0)) | S31: =IF($D31="","",IFERROR(INDEX(Lists!$AK$5:$AK$10,MATCH($D31,Lists!$AJ$5:$AJ$10,0)),"نوع غير معرف")) | T31: =IF($A31="","",IF(COUNTIF($A:$A,$A31)>1,"كود حساب مكرر",IF($B31="","اسم الحساب ناقص",IF(AND($F31="نعم",$G31=""),"الطبيعة ناقصة",IF(AND($F31<>"نعم",OR($M31="",$N31="")),"الحساب الرئيسي يحتاج نطاقًا (من/إلى)",IF(AND($H31=1,$F31<>"نعم"),"حساب نقدية يجب أن يكون قابلًا للترحيل",IF(AND($F31="نعم",$D31=""),"النوع ناقص","")))))))
A32: 1501 | B32: سلف الموظفين | C32: Employee Advances | D32: A | E32: 3 | F32: نعم | G32: مدين | H32: 0 | I32: OPERATING | J32: لا | K32: لا | L32: نعم | P32: =IF($A32="","",IF($F32="نعم",$A32,$M32)) | Q32: =IF($A32="","",IF($F32="نعم",$A32,$N32)) | R32: =IF($A32="","",IF(AND($F32="نعم",$L32<>"لا"),1,0)) | S32: =IF($D32="","",IFERROR(INDEX(Lists!$AK$5:$AK$10,MATCH($D32,Lists!$AJ$5:$AJ$10,0)),"نوع غير معرف")) | T32: =IF($A32="","",IF(COUNTIF($A:$A,$A32)>1,"كود حساب مكرر",IF($B32="","اسم الحساب ناقص",IF(AND($F32="نعم",$G32=""),"الطبيعة ناقصة",IF(AND($F32<>"نعم",OR($M32="",$N32="")),"الحساب الرئيسي يحتاج نطاقًا (من/إلى)",IF(AND($H32=1,$F32<>"نعم"),"حساب نقدية يجب أن يكون قابلًا للترحيل",IF(AND($F32="نعم",$D32=""),"النوع ناقص","")))))))
A33: 1502 | B33: عهد الموظفين | C33: Employee Custody | D33: A | E33: 3 | F33: نعم | G33: مدين | H33: 0 | I33: OPERATING | J33: لا | K33: لا | L33: نعم | P33: =IF($A33="","",IF($F33="نعم",$A33,$M33)) | Q33: =IF($A33="","",IF($F33="نعم",$A33,$N33)) | R33: =IF($A33="","",IF(AND($F33="نعم",$L33<>"لا"),1,0)) | S33: =IF($D33="","",IFERROR(INDEX(Lists!$AK$5:$AK$10,MATCH($D33,Lists!$AJ$5:$AJ$10,0)),"نوع غير معرف")) | T33: =IF($A33="","",IF(COUNTIF($A:$A,$A33)>1,"كود حساب مكرر",IF($B33="","اسم الحساب ناقص",IF(AND($F33="نعم",$G33=""),"الطبيعة ناقصة",IF(AND($F33<>"نعم",OR($M33="",$N33="")),"الحساب الرئيسي يحتاج نطاقًا (من/إلى)",IF(AND($H33=1,$F33<>"نعم"),"حساب نقدية يجب أن يكون قابلًا للترحيل",IF(AND($F33="نعم",$D33=""),"النوع ناقص","")))))))
A34: 1600 | B34: المصروفات المقدمة والضرائب المدينة | C34: Prepaids & Tax Receivable | D34: A | E34: 2 | F34: لا | G34: مدين | H34: 0 | I34: OPERATING | J34: لا | K34: لا | L34: نعم | M34: 1600 | N34: 1699 | P34: =IF($A34="","",IF($F34="نعم",$A34,$M34)) | Q34: =IF($A34="","",IF($F34="نعم",$A34,$N34)) | R34: =IF($A34="","",IF(AND($F34="نعم",$L34<>"لا"),1,0)) | S34: =IF($D34="","",IFERROR(INDEX(Lists!$AK$5:$AK$10,MATCH($D34,Lists!$AJ$5:$AJ$10,0)),"نوع غير معرف")) | T34: =IF($A34="","",IF(COUNTIF($A:$A,$A34)>1,"كود حساب مكرر",IF($B34="","اسم الحساب ناقص",IF(AND($F34="نعم",$G34=""),"الطبيعة ناقصة",IF(AND($F34<>"نعم",OR($M34="",$N34="")),"الحساب الرئيسي يحتاج نطاقًا (من/إلى)",IF(AND($H34=1,$F34<>"نعم"),"حساب نقدية يجب أن يكون قابلًا للترحيل",IF(AND($F34="نعم",$D34=""),"النوع ناقص","")))))))
A35: 1601 | B35: إيجار مدفوع مقدمًا | C35: Prepaid Rent | D35: A | E35: 3 | F35: نعم | G35: مدين | H35: 0 | I35: OPERATING | J35: نعم | K35: نعم | L35: نعم | P35: =IF($A35="","",IF($F35="نعم",$A35,$M35)) | Q35: =IF($A35="","",IF($F35="نعم",$A35,$N35)) | R35: =IF($A35="","",IF(AND($F35="نعم",$L35<>"لا"),1,0)) | S35: =IF($D35="","",IFERROR(INDEX(Lists!$AK$5:$AK$10,MATCH($D35,Lists!$AJ$5:$AJ$10,0)),"نوع غير معرف")) | T35: =IF($A35="","",IF(COUNTIF($A:$A,$A35)>1,"كود حساب مكرر",IF($B35="","اسم الحساب ناقص",IF(AND($F35="نعم",$G35=""),"الطبيعة ناقصة",IF(AND($F35<>"نعم",OR($M35="",$N35="")),"الحساب الرئيسي يحتاج نطاقًا (من/إلى)",IF(AND($H35=1,$F35<>"نعم"),"حساب نقدية يجب أن يكون قابلًا للترحيل",IF(AND($F35="نعم",$D35=""),"النوع ناقص","")))))))
A36: 1602 | B36: تأمينات وتراخيص مدفوعة مقدمًا | C36: Prepaid Insurance & Licences | D36: A | E36: 3 | F36: نعم | G36: مدين | H36: 0 | I36: OPERATING | J36: نعم | K36: نعم | L36: نعم | P36: =IF($A36="","",IF($F36="نعم",$A36,$M36)) | Q36: =IF($A36="","",IF($F36="نعم",$A36,$N36)) | R36: =IF($A36="","",IF(AND($F36="نعم",$L36<>"لا"),1,0)) | S36: =IF($D36="","",IFERROR(INDEX(Lists!$AK$5:$AK$10,MATCH($D36,Lists!$AJ$5:$AJ$10,0)),"نوع غير معرف")) | T36: =IF($A36="","",IF(COUNTIF($A:$A,$A36)>1,"كود حساب مكرر",IF($B36="","اسم الحساب ناقص",IF(AND($F36="نعم",$G36=""),"الطبيعة ناقصة",IF(AND($F36<>"نعم",OR($M36="",$N36="")),"الحساب الرئيسي يحتاج نطاقًا (من/إلى)",IF(AND($H36=1,$F36<>"نعم"),"حساب نقدية يجب أن يكون قابلًا للترحيل",IF(AND($F36="نعم",$D36=""),"النوع ناقص","")))))))
A37: 1603 | B37: مصروفات مدفوعة مقدمًا أخرى | C37: Other Prepaids | D37: A | E37: 3 | F37: نعم | G37: مدين | H37: 0 | I37: OPERATING | J37: نعم | K37: نعم | L37: نعم | P37: =IF($A37="","",IF($F37="نعم",$A37,$M37)) | Q37: =IF($A37="","",IF($F37="نعم",$A37,$N37)) | R37: =IF($A37="","",IF(AND($F37="نعم",$L37<>"لا"),1,0)) | S37: =IF($D37="","",IFERROR(INDEX(Lists!$AK$5:$AK$10,MATCH($D37,Lists!$AJ$5:$AJ$10,0)),"نوع غير معرف")) | T37: =IF($A37="","",IF(COUNTIF($A:$A,$A37)>1,"كود حساب مكرر",IF($B37="","اسم الحساب ناقص",IF(AND($F37="نعم",$G37=""),"الطبيعة ناقصة",IF(AND($F37<>"نعم",OR($M37="",$N37="")),"الحساب الرئيسي يحتاج نطاقًا (من/إلى)",IF(AND($H37=1,$F37<>"نعم"),"حساب نقدية يجب أن يكون قابلًا للترحيل",IF(AND($F37="نعم",$D37=""),"النوع ناقص","")))))))
A38: 1610 | B38: ضريبة قيمة مضافة - مدخلات | C38: VAT Input | D38: A | E38: 3 | F38: نعم | G38: مدين | H38: 0 | I38: OPERATING | J38: لا | K38: لا | L38: نعم | O38: تُستخدم فقط عند تفعيل الضريبة | P38: =IF($A38="","",IF($F38="نعم",$A38,$M38)) | Q38: =IF($A38="","",IF($F38="نعم",$A38,$N38)) | R38: =IF($A38="","",IF(AND($F38="نعم",$L38<>"لا"),1,0)) | S38: =IF($D38="","",IFERROR(INDEX(Lists!$AK$5:$AK$10,MATCH($D38,Lists!$AJ$5:$AJ$10,0)),"نوع غير معرف")) | T38: =IF($A38="","",IF(COUNTIF($A:$A,$A38)>1,"كود حساب مكرر",IF($B38="","اسم الحساب ناقص",IF(AND($F38="نعم",$G38=""),"الطبيعة ناقصة",IF(AND($F38<>"نعم",OR($M38="",$N38="")),"الحساب الرئيسي يحتاج نطاقًا (من/إلى)",IF(AND($H38=1,$F38<>"نعم"),"حساب نقدية يجب أن يكون قابلًا للترحيل",IF(AND($F38="نعم",$D38=""),"النوع ناقص","")))))))
A39: 1700 | B39: الأصول الثابتة | C39: Fixed Assets | D39: A | E39: 2 | F39: لا | G39: مدين | H39: 0 | I39: OPERATING | J39: لا | K39: لا | L39: نعم | M39: 1700 | N39: 1799 | P39: =IF($A39="","",IF($F39="نعم",$A39,$M39)) | Q39: =IF($A39="","",IF($F39="نعم",$A39,$N39)) | R39: =IF($A39="","",IF(AND($F39="نعم",$L39<>"لا"),1,0)) | S39: =IF($D39="","",IFERROR(INDEX(Lists!$AK$5:$AK$10,MATCH($D39,Lists!$AJ$5:$AJ$10,0)),"نوع غير معرف")) | T39: =IF($A39="","",IF(COUNTIF($A:$A,$A39)>1,"كود حساب مكرر",IF($B39="","اسم الحساب ناقص",IF(AND($F39="نعم",$G39=""),"الطبيعة ناقصة",IF(AND($F39<>"نعم",OR($M39="",$N39="")),"الحساب الرئيسي يحتاج نطاقًا (من/إلى)",IF(AND($H39=1,$F39<>"نعم"),"حساب نقدية يجب أن يكون قابلًا للترحيل",IF(AND($F39="نعم",$D39=""),"النوع ناقص","")))))))
A40: 1701 | B40: معدات المطابخ والأفران | C40: Kitchen Equipment & Ovens | D40: A | E40: 3 | F40: نعم | G40: مدين | H40: 0 | I40: INVESTING | J40: لا | K40: نعم | L40: نعم | P40: =IF($A40="","",IF($F40="نعم",$A40,$M40)) | Q40: =IF($A40="","",IF($F40="نعم",$A40,$N40)) | R40: =IF($A40="","",IF(AND($F40="نعم",$L40<>"لا"),1,0)) | S40: =IF($D40="","",IFERROR(INDEX(Lists!$AK$5:$AK$10,MATCH($D40,Lists!$AJ$5:$AJ$10,0)),"نوع غير معرف")) | T40: =IF($A40="","",IF(COUNTIF($A:$A,$A40)>1,"كود حساب مكرر",IF($B40="","اسم الحساب ناقص",IF(AND($F40="نعم",$G40=""),"الطبيعة ناقصة",IF(AND($F40<>"نعم",OR($M40="",$N40="")),"الحساب الرئيسي يحتاج نطاقًا (من/إلى)",IF(AND($H40=1,$F40<>"نعم"),"حساب نقدية يجب أن يكون قابلًا للترحيل",IF(AND($F40="نعم",$D40=""),"النوع ناقص","")))))))
...

Sheet Locations
