Workbook

Sheet لوحة التحكم
A1: لوحة تحكم Cost Control - Satamoni (أكتوبر 2026)
A3: عدد الأصناف (بريسبي كامل) | B3: متوسط % تكلفة الطعام | C3: متوسط % Prime Cost | D3: عدد الأصناف فوق الهدف | E3: متوسط % هامش الربح
A4: =COUNTIFS('تحليل التكلفة والسعر'!$C$2:$C$700,">0") -> 189 | B4: =IFERROR(AVERAGEIFS('تحليل التكلفة والسعر'!$E$2:$E$700,'تحليل التكلفة والسعر'!$C$2:$C$700,">0"),"") -> 0.46717664 | C4: =IFERROR(AVERAGEIFS('تحليل التكلفة والسعر'!$K$2:$K$700,'تحليل التكلفة والسعر'!$C$2:$C$700,">0"),"") -> 0.71717664 | D4: =SUMPRODUCT((ISNUMBER('تحليل التكلفة والسعر'!$C$2:$C$700))*('تحليل التكلفة والسعر'!$C$2:$C$700>0)*(ISNUMBER('تحليل التكلفة والسعر'!$E$2:$E$700))*('تحليل التكلفة والسعر'!$E$2:$E$700>'تحليل التكلفة والسعر'!$F$2:$F$700)) -> 156 | E4: =IFERROR(AVERAGEIFS('تحليل التكلفة والسعر'!$I$2:$I$700,'تحليل التكلفة والسعر'!$C$2:$C$700,">0"),"") -> 0.53282336
A6: متوسط التكلفة حسب القسم
A7: القسم | B7: عدد الأصناف | C7: متوسط % تكلفة الطعام | D7: متوسط % Prime Cost
A8: قسم البيتزا | B8: =COUNTIF('تحليل التكلفة والسعر'!$A$2:$A$700,$A8) -> 22 | C8: =IFERROR(AVERAGEIFS('تحليل التكلفة والسعر'!$E$2:$E$700,'تحليل التكلفة والسعر'!$A$2:$A$700,$A8,'تحليل التكلفة والسعر'!$C$2:$C$700,">0"),"") -> 0.51578697 | D8: =IFERROR(AVERAGEIFS('تحليل التكلفة والسعر'!$K$2:$K$700,'تحليل التكلفة والسعر'!$A$2:$A$700,$A8,'تحليل التكلفة والسعر'!$C$2:$C$700,">0"),"") -> 0.76578697
A9: قسم الفطير الحادق | B9: =COUNTIF('تحليل التكلفة والسعر'!$A$2:$A$700,$A9) -> 23 | C9: =IFERROR(AVERAGEIFS('تحليل التكلفة والسعر'!$E$2:$E$700,'تحليل التكلفة والسعر'!$A$2:$A$700,$A9,'تحليل التكلفة والسعر'!$C$2:$C$700,">0"),"") -> 0.51352334 | D9: =IFERROR(AVERAGEIFS('تحليل التكلفة والسعر'!$K$2:$K$700,'تحليل التكلفة والسعر'!$A$2:$A$700,$A9,'تحليل التكلفة والسعر'!$C$2:$C$700,">0"),"") -> 0.76352334
A10: قسم الفطير الحلو | B10: =COUNTIF('تحليل التكلفة والسعر'!$A$2:$A$700,$A10) -> 7 | C10: =IFERROR(AVERAGEIFS('تحليل التكلفة والسعر'!$E$2:$E$700,'تحليل التكلفة والسعر'!$A$2:$A$700,$A10,'تحليل التكلفة والسعر'!$C$2:$C$700,">0"),"") -> 0.52144595 | D10: =IFERROR(AVERAGEIFS('تحليل التكلفة والسعر'!$K$2:$K$700,'تحليل التكلفة والسعر'!$A$2:$A$700,$A10,'تحليل التكلفة والسعر'!$C$2:$C$700,">0"),"") -> 0.77144595
A11: قسم البرجر | B11: =COUNTIF('تحليل التكلفة والسعر'!$A$2:$A$700,$A11) -> 6 | C11: =IFERROR(AVERAGEIFS('تحليل التكلفة والسعر'!$E$2:$E$700,'تحليل التكلفة والسعر'!$A$2:$A$700,$A11,'تحليل التكلفة والسعر'!$C$2:$C$700,">0"),"") -> 0.53828188 | D11: =IFERROR(AVERAGEIFS('تحليل التكلفة والسعر'!$K$2:$K$700,'تحليل التكلفة والسعر'!$A$2:$A$700,$A11,'تحليل التكلفة والسعر'!$C$2:$C$700,">0"),"") -> 0.78828188
A12: قسم المكرونات | B12: =COUNTIF('تحليل التكلفة والسعر'!$A$2:$A$700,$A12) -> 7 | C12: =IFERROR(AVERAGEIFS('تحليل التكلفة والسعر'!$E$2:$E$700,'تحليل التكلفة والسعر'!$A$2:$A$700,$A12,'تحليل التكلفة والسعر'!$C$2:$C$700,">0"),"") -> 0.53488757 | D12: =IFERROR(AVERAGEIFS('تحليل التكلفة والسعر'!$K$2:$K$700,'تحليل التكلفة والسعر'!$A$2:$A$700,$A12,'تحليل التكلفة والسعر'!$C$2:$C$700,">0"),"") -> 0.78488757
A13: قسم الكريب | B13: =COUNTIF('تحليل التكلفة والسعر'!$A$2:$A$700,$A13) -> 8 | C13: =IFERROR(AVERAGEIFS('تحليل التكلفة والسعر'!$E$2:$E$700,'تحليل التكلفة والسعر'!$A$2:$A$700,$A13,'تحليل التكلفة والسعر'!$C$2:$C$700,">0"),"") -> 0.59655685 | D13: =IFERROR(AVERAGEIFS('تحليل التكلفة والسعر'!$K$2:$K$700,'تحليل التكلفة والسعر'!$A$2:$A$700,$A13,'تحليل التكلفة والسعر'!$C$2:$C$700,">0"),"") -> 0.84655685
A14: قسم البطاطس | B14: =COUNTIF('تحليل التكلفة والسعر'!$A$2:$A$700,$A14) -> 4 | C14: =IFERROR(AVERAGEIFS('تحليل التكلفة والسعر'!$E$2:$E$700,'تحليل التكلفة والسعر'!$A$2:$A$700,$A14,'تحليل التكلفة والسعر'!$C$2:$C$700,">0"),"") -> 0.42991956 | D14: =IFERROR(AVERAGEIFS('تحليل التكلفة والسعر'!$K$2:$K$700,'تحليل التكلفة والسعر'!$A$2:$A$700,$A14,'تحليل التكلفة والسعر'!$C$2:$C$700,">0"),"") -> 0.67991956
A15: قسم البيتزا الصيامي | B15: =COUNTIF('تحليل التكلفة والسعر'!$A$2:$A$700,$A15) -> 16 | C15: =IFERROR(AVERAGEIFS('تحليل التكلفة والسعر'!$E$2:$E$700,'تحليل التكلفة والسعر'!$A$2:$A$700,$A15,'تحليل التكلفة والسعر'!$C$2:$C$700,">0"),"") -> 0.45000052 | D15: =IFERROR(AVERAGEIFS('تحليل التكلفة والسعر'!$K$2:$K$700,'تحليل التكلفة والسعر'!$A$2:$A$700,$A15,'تحليل التكلفة والسعر'!$C$2:$C$700,">0"),"") -> 0.70000052
A16: قسم الفطير الحادق الصيامي | B16: =COUNTIF('تحليل التكلفة والسعر'!$A$2:$A$700,$A16) -> 18 | C16: =IFERROR(AVERAGEIFS('تحليل التكلفة والسعر'!$E$2:$E$700,'تحليل التكلفة والسعر'!$A$2:$A$700,$A16,'تحليل التكلفة والسعر'!$C$2:$C$700,">0"),"") -> 0.43161676 | D16: =IFERROR(AVERAGEIFS('تحليل التكلفة والسعر'!$K$2:$K$700,'تحليل التكلفة والسعر'!$A$2:$A$700,$A16,'تحليل التكلفة والسعر'!$C$2:$C$700,">0"),"") -> 0.68161676
A17: قسم الفطير الحلو الصيامي | B17: =COUNTIF('تحليل التكلفة والسعر'!$A$2:$A$700,$A17) -> 4 | C17: =IFERROR(AVERAGEIFS('تحليل التكلفة والسعر'!$E$2:$E$700,'تحليل التكلفة والسعر'!$A$2:$A$700,$A17,'تحليل التكلفة والسعر'!$C$2:$C$700,">0"),"") -> 0.39545884 | D17: =IFERROR(AVERAGEIFS('تحليل التكلفة والسعر'!$K$2:$K$700,'تحليل التكلفة والسعر'!$A$2:$A$700,$A17,'تحليل التكلفة والسعر'!$C$2:$C$700,">0"),"") -> 0.64545884
A18: قسم البرجر الصيامي | B18: =COUNTIF('تحليل التكلفة والسعر'!$A$2:$A$700,$A18) -> 4 | C18: =IFERROR(AVERAGEIFS('تحليل التكلفة والسعر'!$E$2:$E$700,'تحليل التكلفة والسعر'!$A$2:$A$700,$A18,'تحليل التكلفة والسعر'!$C$2:$C$700,">0"),"") -> 0.41592541 | D18: =IFERROR(AVERAGEIFS('تحليل التكلفة والسعر'!$K$2:$K$700,'تحليل التكلفة والسعر'!$A$2:$A$700,$A18,'تحليل التكلفة والسعر'!$C$2:$C$700,">0"),"") -> 0.66592541
A19: قسم المكرونات الصيامي | B19: =COUNTIF('تحليل التكلفة والسعر'!$A$2:$A$700,$A19) -> 5 | C19: =IFERROR(AVERAGEIFS('تحليل التكلفة والسعر'!$E$2:$E$700,'تحليل التكلفة والسعر'!$A$2:$A$700,$A19,'تحليل التكلفة والسعر'!$C$2:$C$700,">0"),"") -> 0.44223055 | D19: =IFERROR(AVERAGEIFS('تحليل التكلفة والسعر'!$K$2:$K$700,'تحليل التكلفة والسعر'!$A$2:$A$700,$A19,'تحليل التكلفة والسعر'!$C$2:$C$700,">0"),"") -> 0.69223055
A20: قسم الكريب الصيامي | B20: =COUNTIF('تحليل التكلفة والسعر'!$A$2:$A$700,$A20) -> 4 | C20: =IFERROR(AVERAGEIFS('تحليل التكلفة والسعر'!$E$2:$E$700,'تحليل التكلفة والسعر'!$A$2:$A$700,$A20,'تحليل التكلفة والسعر'!$C$2:$C$700,">0"),"") -> 0.46022013 | D20: =IFERROR(AVERAGEIFS('تحليل التكلفة والسعر'!$K$2:$K$700,'تحليل التكلفة والسعر'!$A$2:$A$700,$A20,'تحليل التكلفة والسعر'!$C$2:$C$700,">0"),"") -> 0.71022013
A23: أعلى 5 أصناف هامش ربح
A24: اسم الصنف | B24: سعر البيع | C24: % تكلفة الطعام | D24: % هامش الربح
A25: =IFERROR(INDEX('تحليل التكلفة والسعر'!$B$2:$B$700,MATCH(LARGE('تحليل التكلفة والسعر'!$L$2:$L$700,1),'تحليل التكلفة والسعر'!$L$2:$L$700,0)),"") -> اضافة حشو للاطراف (Small) | B25: =IFERROR(INDEX('تحليل التكلفة والسعر'!$D$2:$D$700,MATCH(LARGE('تحليل التكلفة والسعر'!$L$2:$L$700,1),'تحليل التكلفة والسعر'!$L$2:$L$700,0)),"") -> 50 | C25: =IFERROR(INDEX('تحليل التكلفة والسعر'!$E$2:$E$700,MATCH(LARGE('تحليل التكلفة والسعر'!$L$2:$L$700,1),'تحليل التكلفة والسعر'!$L$2:$L$700,0)),"") -> 0.218638 | D25: =IFERROR(INDEX('تحليل التكلفة والسعر'!$I$2:$I$700,MATCH(LARGE('تحليل التكلفة والسعر'!$L$2:$L$700,1),'تحليل التكلفة والسعر'!$L$2:$L$700,0)),"") -> 0.781362
A26: =IFERROR(INDEX('تحليل التكلفة والسعر'!$B$2:$B$700,MATCH(LARGE('تحليل التكلفة والسعر'!$L$2:$L$700,2),'تحليل التكلفة والسعر'!$L$2:$L$700,0)),"") -> صوص باربيكيو إضافي (M) | B26: =IFERROR(INDEX('تحليل التكلفة والسعر'!$D$2:$D$700,MATCH(LARGE('تحليل التكلفة والسعر'!$L$2:$L$700,2),'تحليل التكلفة والسعر'!$L$2:$L$700,0)),"") -> 34.5 | C26: =IFERROR(INDEX('تحليل التكلفة والسعر'!$E$2:$E$700,MATCH(LARGE('تحليل التكلفة والسعر'!$L$2:$L$700,2),'تحليل التكلفة والسعر'!$L$2:$L$700,0)),"") -> 0.22991014 | D26: =IFERROR(INDEX('تحليل التكلفة والسعر'!$I$2:$I$700,MATCH(LARGE('تحليل التكلفة والسعر'!$L$2:$L$700,2),'تحليل التكلفة والسعر'!$L$2:$L$700,0)),"") -> 0.77008986
A27: =IFERROR(INDEX('تحليل التكلفة والسعر'!$B$2:$B$700,MATCH(LARGE('تحليل التكلفة والسعر'!$L$2:$L$700,3),'تحليل التكلفة والسعر'!$L$2:$L$700,0)),"") -> اضافة فراخ كريسبي (فطير كبير) | B27: =IFERROR(INDEX('تحليل التكلفة والسعر'!$D$2:$D$700,MATCH(LARGE('تحليل التكلفة والسعر'!$L$2:$L$700,3),'تحليل التكلفة والسعر'!$L$2:$L$700,0)),"") -> 130 | C27: =IFERROR(INDEX('تحليل التكلفة والسعر'!$E$2:$E$700,MATCH(LARGE('تحليل التكلفة والسعر'!$L$2:$L$700,3),'تحليل التكلفة والسعر'!$L$2:$L$700,0)),"") -> 0.23024538 | D27: =IFERROR(INDEX('تحليل التكلفة والسعر'!$I$2:$I$700,MATCH(LARGE('تحليل التكلفة والسعر'!$L$2:$L$700,3),'تحليل التكلفة والسعر'!$L$2:$L$700,0)),"") -> 0.76975462
A28: =IFERROR(INDEX('تحليل التكلفة والسعر'!$B$2:$B$700,MATCH(LARGE('تحليل التكلفة والسعر'!$L$2:$L$700,4),'تحليل التكلفة والسعر'!$L$2:$L$700,0)),"") -> اضافة جبنة رومي (فطير وسط) | B28: =IFERROR(INDEX('تحليل التكلفة والسعر'!$D$2:$D$700,MATCH(LARGE('تحليل التكلفة والسعر'!$L$2:$L$700,4),'تحليل التكلفة والسعر'!$L$2:$L$700,0)),"") -> 40 | C28: =IFERROR(INDEX('تحليل التكلفة والسعر'!$E$2:$E$700,MATCH(LARGE('تحليل التكلفة والسعر'!$L$2:$L$700,4),'تحليل التكلفة والسعر'!$L$2:$L$700,0)),"") -> 0.2482975 | D28: =IFERROR(INDEX('تحليل التكلفة والسعر'!$I$2:$I$700,MATCH(LARGE('تحليل التكلفة والسعر'!$L$2:$L$700,4),'تحليل التكلفة والسعر'!$L$2:$L$700,0)),"") -> 0.7517025
A29: =IFERROR(INDEX('تحليل التكلفة والسعر'!$B$2:$B$700,MATCH(LARGE('تحليل التكلفة والسعر'!$L$2:$L$700,5),'تحليل التكلفة والسعر'!$L$2:$L$700,0)),"") -> اضافة جبنة رومي (بيتزا وسط) | B29: =IFERROR(INDEX('تحليل التكلفة والسعر'!$D$2:$D$700,MATCH(LARGE('تحليل التكلفة والسعر'!$L$2:$L$700,5),'تحليل التكلفة والسعر'!$L$2:$L$700,0)),"") -> 40 | C29: =IFERROR(INDEX('تحليل التكلفة والسعر'!$E$2:$E$700,MATCH(LARGE('تحليل التكلفة والسعر'!$L$2:$L$700,5),'تحليل التكلفة والسعر'!$L$2:$L$700,0)),"") -> 0.2482975 | D29: =IFERROR(INDEX('تحليل التكلفة والسعر'!$I$2:$I$700,MATCH(LARGE('تحليل التكلفة والسعر'!$L$2:$L$700,5),'تحليل التكلفة والسعر'!$L$2:$L$700,0)),"") -> 0.7517025
A31: أقل 5 أصناف هامش ربح (محتاجة مراجعة)
A32: اسم الصنف | B32: سعر البيع | C32: % تكلفة الطعام | D32: % هامش الربح
A33: =IFERROR(INDEX('تحليل التكلفة والسعر'!$B$2:$B$700,MATCH(SMALL('تحليل التكلفة والسعر'!$L$2:$L$700,1),'تحليل التكلفة والسعر'!$L$2:$L$700,0)),"") -> عيش كريب | B33: =IFERROR(INDEX('تحليل التكلفة والسعر'!$D$2:$D$700,MATCH(SMALL('تحليل التكلفة والسعر'!$L$2:$L$700,1),'تحليل التكلفة والسعر'!$L$2:$L$700,0)),"") -> 5 | C33: =IFERROR(INDEX('تحليل التكلفة والسعر'!$E$2:$E$700,MATCH(SMALL('تحليل التكلفة والسعر'!$L$2:$L$700,1),'تحليل التكلفة والسعر'!$L$2:$L$700,0)),"") -> 1.1889924 | D33: =IFERROR(INDEX('تحليل التكلفة والسعر'!$I$2:$I$700,MATCH(SMALL('تحليل التكلفة والسعر'!$L$2:$L$700,1),'تحليل التكلفة والسعر'!$L$2:$L$700,0)),"") -> -0.18899242
A34: =IFERROR(INDEX('تحليل التكلفة والسعر'!$B$2:$B$700,MATCH(SMALL('تحليل التكلفة والسعر'!$L$2:$L$700,2),'تحليل التكلفة والسعر'!$L$2:$L$700,0)),"") -> مياه معدنية M | B34: =IFERROR(INDEX('تحليل التكلفة والسعر'!$D$2:$D$700,MATCH(SMALL('تحليل التكلفة والسعر'!$L$2:$L$700,2),'تحليل التكلفة والسعر'!$L$2:$L$700,0)),"") -> 8 | C34: =IFERROR(INDEX('تحليل التكلفة والسعر'!$E$2:$E$700,MATCH(SMALL('تحليل التكلفة والسعر'!$L$2:$L$700,2),'تحليل التكلفة والسعر'!$L$2:$L$700,0)),"") -> 0.9914875 | D34: =IFERROR(INDEX('تحليل التكلفة والسعر'!$I$2:$I$700,MATCH(SMALL('تحليل التكلفة والسعر'!$L$2:$L$700,2),'تحليل التكلفة والسعر'!$L$2:$L$700,0)),"") -> 0.0085125
A35: =IFERROR(INDEX('تحليل التكلفة والسعر'!$B$2:$B$700,MATCH(SMALL('تحليل التكلفة والسعر'!$L$2:$L$700,3),'تحليل التكلفة والسعر'!$L$2:$L$700,0)),"") -> بيبسي 2 لتر | B35: =IFERROR(INDEX('تحليل التكلفة والسعر'!$D$2:$D$700,MATCH(SMALL('تحليل التكلفة والسعر'!$L$2:$L$700,3),'تحليل التكلفة والسعر'!$L$2:$L$700,0)),"") -> 45 | C35: =IFERROR(INDEX('تحليل التكلفة والسعر'!$E$2:$E$700,MATCH(SMALL('تحليل التكلفة والسعر'!$L$2:$L$700,3),'تحليل التكلفة والسعر'!$L$2:$L$700,0)),"") -> 0.90959778 | D35: =IFERROR(INDEX('تحليل التكلفة والسعر'!$I$2:$I$700,MATCH(SMALL('تحليل التكلفة والسعر'!$L$2:$L$700,3),'تحليل التكلفة والسعر'!$L$2:$L$700,0)),"") -> 0.090402222
A36: =IFERROR(INDEX('تحليل التكلفة والسعر'!$B$2:$B$700,MATCH(SMALL('تحليل التكلفة والسعر'!$L$2:$L$700,4),'تحليل التكلفة والسعر'!$L$2:$L$700,0)),"") -> بيبسي لتر | B36: =IFERROR(INDEX('تحليل التكلفة والسعر'!$D$2:$D$700,MATCH(SMALL('تحليل التكلفة والسعر'!$L$2:$L$700,4),'تحليل التكلفة والسعر'!$L$2:$L$700,0)),"") -> 35 | C36: =IFERROR(INDEX('تحليل التكلفة والسعر'!$E$2:$E$700,MATCH(SMALL('تحليل التكلفة والسعر'!$L$2:$L$700,4),'تحليل التكلفة والسعر'!$L$2:$L$700,0)),"") -> 0.88376857 | D36: =IFERROR(INDEX('تحليل التكلفة والسعر'!$I$2:$I$700,MATCH(SMALL('تحليل التكلفة والسعر'!$L$2:$L$700,4),'تحليل التكلفة والسعر'!$L$2:$L$700,0)),"") -> 0.11623143
A37: =IFERROR(INDEX('تحليل التكلفة والسعر'!$B$2:$B$700,MATCH(SMALL('تحليل التكلفة والسعر'!$L$2:$L$700,5),'تحليل التكلفة والسعر'!$L$2:$L$700,0)),"") -> اضافة جمبري (بيتزا وسط) | B37: =IFERROR(INDEX('تحليل التكلفة والسعر'!$D$2:$D$700,MATCH(SMALL('تحليل التكلفة والسعر'!$L$2:$L$700,5),'تحليل التكلفة والسعر'!$L$2:$L$700,0)),"") -> 140 | C37: =IFERROR(INDEX('تحليل التكلفة والسعر'!$E$2:$E$700,MATCH(SMALL('تحليل التكلفة والسعر'!$L$2:$L$700,5),'تحليل التكلفة والسعر'!$L$2:$L$700,0)),"") -> 0.68522786 | D37: =IFERROR(INDEX('تحليل التكلفة والسعر'!$I$2:$I$700,MATCH(SMALL('تحليل التكلفة والسعر'!$L$2:$L$700,5),'تحليل التكلفة والسعر'!$L$2:$L$700,0)),"") -> 0.31477214
A39: ملحوظة: الجدولين أعلاه بيتحدثوا أوتوماتيك مع أي تعديل في شيت تحليل التكلفة والسعر.

Sheet داشبورد المخزون
A1: داشبورد المالك - الجرد والمخزون
A2: ="بيانات لحد يوم: "&TEXT('إعدادات المخزون'!$B$4,"yyyy-mm-dd")&" | بداية الفترة: "&TEXT('إعدادات المخزون'!$B$5,"yyyy-mm-dd")&" | نسبة التسامح: "&TEXT('إعدادات المخزون'!$B$7,"0.0%") -> بيانات لحد يوم: 2026-10-12 | بداية الفترة: 2026-10-01 | نسبة التسامح: 3.0%
A3: غيّر "تاريخ التقرير" من شيت إعدادات المخزون. الأرقام التراكمية = من بداية الشهر لحد التاريخ، وأرقام "اليوم" = اليوم نفسه.
A5: المؤشر | B5: محرم بك | C5: ابراهيمية | D5: عصافرة | E5: الإجمالي
A6: — الجرد (تراكمي من بداية الشهر) —
A7: عدد المواد المتتبعة | B7: =89 -> 89 | C7: =89 -> 89 | D7: =89 -> 89 | E7: =MAX(B7:D7) -> 89
A8: اتجرد النهاردة | B8: =COUNTIF('جرد - محرم بك'!$K$7:$K$95,"نعم") -> 0 | C8: =COUNTIF('جرد - ابراهيمية'!$K$7:$K$95,"نعم") -> 0 | D8: =COUNTIF('جرد - عصافرة'!$K$7:$K$95,"نعم") -> 0 | E8: =SUM(B8:D8) -> 0
A9: نسبة إتمام الجرد | B9: =IFERROR(COUNTIF('جرد - محرم بك'!$K$7:$K$95,"نعم")/89,0) -> 0 | C9: =IFERROR(COUNTIF('جرد - ابراهيمية'!$K$7:$K$95,"نعم")/89,0) -> 0 | D9: =IFERROR(COUNTIF('جرد - عصافرة'!$K$7:$K$95,"نعم")/89,0) -> 0 | E9: =AVERAGE(B9:D9) -> 0
A10: قيمة المخزون الدفتري (جنيه) | B10: =SUMPRODUCT('جرد - محرم بك'!$J$7:$J$95,'جرد - محرم بك'!$C$7:$C$95) -> 65102.777 | C10: =SUMPRODUCT('جرد - ابراهيمية'!$J$7:$J$95,'جرد - ابراهيمية'!$C$7:$C$95) -> 71951.429 | D10: =SUMPRODUCT('جرد - عصافرة'!$J$7:$J$95,'جرد - عصافرة'!$C$7:$C$95) -> 86384.454 | E10: =SUM(B10:D10) -> 223438.66
A11: إجمالي العجز (جنيه) | B11: =SUMIF('جرد - محرم بك'!$AA$7:$AA$95,"<0") -> 0 | C11: =SUMIF('جرد - ابراهيمية'!$AA$7:$AA$95,"<0") -> 0 | D11: =SUMIF('جرد - عصافرة'!$AA$7:$AA$95,"<0") -> 0 | E11: =SUM(B11:D11) -> 0
A12: إجمالي الزيادة (جنيه) | B12: =SUMIF('جرد - محرم بك'!$AA$7:$AA$95,">0") -> 0 | C12: =SUMIF('جرد - ابراهيمية'!$AA$7:$AA$95,">0") -> 0 | D12: =SUMIF('جرد - عصافرة'!$AA$7:$AA$95,">0") -> 0 | E12: =SUM(B12:D12) -> 0
A13: صافي الفرق (جنيه) | B13: =SUM('جرد - محرم بك'!$AA$7:$AA$95) -> 0 | C13: =SUM('جرد - ابراهيمية'!$AA$7:$AA$95) -> 0 | D13: =SUM('جرد - عصافرة'!$AA$7:$AA$95) -> 0 | E13: =SUM(B13:D13) -> 0
A14: معدل الانحراف % | B14: =IFERROR(SUMPRODUCT(ABS('جرد - محرم بك'!$AA$7:$AA$95))/SUM('جرد - محرم بك'!$AB$7:$AB$95),0) -> 0 | C14: =IFERROR(SUMPRODUCT(ABS('جرد - ابراهيمية'!$AA$7:$AA$95))/SUM('جرد - ابراهيمية'!$AB$7:$AB$95),0) -> 0 | D14: =IFERROR(SUMPRODUCT(ABS('جرد - عصافرة'!$AA$7:$AA$95))/SUM('جرد - عصافرة'!$AB$7:$AB$95),0) -> 0 | E14: =IFERROR((SUMPRODUCT(ABS('جرد - محرم بك'!$AA$7:$AA$95))+SUMPRODUCT(ABS('جرد - ابراهيمية'!$AA$7:$AA$95))+SUMPRODUCT(ABS('جرد - عصافرة'!$AA$7:$AA$95)))/(SUM('جرد - محرم بك'!$AB$7:$AB$95)+SUM('جرد - ابراهيمية'!$AB$7:$AB$95)+SUM('جرد - عصافرة'!$AB$7:$AB$95)),0) -> 0
A15: مواد خارج التسامح | B15: =COUNTIF('جرد - محرم بك'!$P$7:$P$95,"عجز")+COUNTIF('جرد - محرم بك'!$P$7:$P$95,"زيادة") -> 0 | C15: =COUNTIF('جرد - ابراهيمية'!$P$7:$P$95,"عجز")+COUNTIF('جرد - ابراهيمية'!$P$7:$P$95,"زيادة") -> 0 | D15: =COUNTIF('جرد - عصافرة'!$P$7:$P$95,"عجز")+COUNTIF('جرد - عصافرة'!$P$7:$P$95,"زيادة") -> 0 | E15: =SUM(B15:D15) -> 0
A16: — الجرد اليومي —
A17: عجز اليوم (جنيه) | B17: =SUMIF('جرد - محرم بك'!$AC$7:$AC$95,"<0") -> 0 | C17: =SUMIF('جرد - ابراهيمية'!$AC$7:$AC$95,"<0") -> 0 | D17: =SUMIF('جرد - عصافرة'!$AC$7:$AC$95,"<0") -> 0 | E17: =SUM(B17:D17) -> 0
A18: زيادة اليوم (جنيه) | B18: =SUMIF('جرد - محرم بك'!$AC$7:$AC$95,">0") -> 0 | C18: =SUMIF('جرد - ابراهيمية'!$AC$7:$AC$95,">0") -> 0 | D18: =SUMIF('جرد - عصافرة'!$AC$7:$AC$95,">0") -> 0 | E18: =SUM(B18:D18) -> 0
A19: — المبيعات والمشتريات —
A20: إيراد اليوم (جنيه) | B20: =SUMIFS('مبيعات يومية'!$F$2:$F$14001,'مبيعات يومية'!$B$2:$B$14001,'إعدادات المخزون'!$A$15,'مبيعات يومية'!$A$2:$A$14001,'إعدادات المخزون'!$B$4) -> 25466.228 | C20: =SUMIFS('مبيعات يومية'!$F$2:$F$14001,'مبيعات يومية'!$B$2:$B$14001,'إعدادات المخزون'!$A$16,'مبيعات يومية'!$A$2:$A$14001,'إعدادات المخزون'!$B$4) -> 23196.761 | D20: =SUMIFS('مبيعات يومية'!$F$2:$F$14001,'مبيعات يومية'!$B$2:$B$14001,'إعدادات المخزون'!$A$17,'مبيعات يومية'!$A$2:$A$14001,'إعدادات المخزون'!$B$4) -> 26153.319 | E20: =SUM(B20:D20) -> 74816.308
A21: إيراد الشهر (جنيه) | B21: =SUMIFS('مبيعات يومية'!$F$2:$F$14001,'مبيعات يومية'!$B$2:$B$14001,'إعدادات المخزون'!$A$15,'مبيعات يومية'!$A$2:$A$14001,">="&'إعدادات المخزون'!$B$5,'مبيعات يومية'!$A$2:$A$14001,"<="&'إعدادات المخزون'!$B$4) -> 305594.74 | C21: =SUMIFS('مبيعات يومية'!$F$2:$F$14001,'مبيعات يومية'!$B$2:$B$14001,'إعدادات المخزون'!$A$16,'مبيعات يومية'!$A$2:$A$14001,">="&'إعدادات المخزون'!$B$5,'مبيعات يومية'!$A$2:$A$14001,"<="&'إعدادات المخزون'!$B$4) -> 278361.13 | D21: =SUMIFS('مبيعات يومية'!$F$2:$F$14001,'مبيعات يومية'!$B$2:$B$14001,'إعدادات المخزون'!$A$17,'مبيعات يومية'!$A$2:$A$14001,">="&'إعدادات المخزون'!$B$5,'مبيعات يومية'!$A$2:$A$14001,"<="&'إعدادات المخزون'!$B$4) -> 313839.83 | E21: =SUM(B21:D21) -> 897795.7
A22: تكلفة المبيعات النظرية - الشهر (جنيه) | B22: =SUMIFS('مبيعات يومية'!$G$2:$G$14001,'مبيعات يومية'!$B$2:$B$14001,'إعدادات المخزون'!$A$15,'مبيعات يومية'!$A$2:$A$14001,">="&'إعدادات المخزون'!$B$5,'مبيعات يومية'!$A$2:$A$14001,"<="&'إعدادات المخزون'!$B$4) -> 167160.73 | C22: =SUMIFS('مبيعات يومية'!$G$2:$G$14001,'مبيعات يومية'!$B$2:$B$14001,'إعدادات المخزون'!$A$16,'مبيعات يومية'!$A$2:$A$14001,">="&'إعدادات المخزون'!$B$5,'مبيعات يومية'!$A$2:$A$14001,"<="&'إعدادات المخزون'!$B$4) -> 150387.25 | D22: =SUMIFS('مبيعات يومية'!$G$2:$G$14001,'مبيعات يومية'!$B$2:$B$14001,'إعدادات المخزون'!$A$17,'مبيعات يومية'!$A$2:$A$14001,">="&'إعدادات المخزون'!$B$5,'مبيعات يومية'!$A$2:$A$14001,"<="&'إعدادات المخزون'!$B$4) -> 170441.29 | E22: =SUM(B22:D22) -> 487989.27
A23: % تكلفة نظرية من الإيراد | B23: =IFERROR(B22/B21,0) -> 0.54700134 | C23: =IFERROR(C22/C21,0) -> 0.54025953 | D23: =IFERROR(D22/D21,0) -> 0.54308367 | E23: =IFERROR(E22/E21,0) -> 0.54354156
A24: مشتريات اليوم (جنيه) | B24: =SUMIFS('مشتريات يومية'!$E$2:$E$4001,'مشتريات يومية'!$B$2:$B$4001,'إعدادات المخزون'!$A$15,'مشتريات يومية'!$A$2:$A$4001,'إعدادات المخزون'!$B$4) -> 0 | C24: =SUMIFS('مشتريات يومية'!$E$2:$E$4001,'مشتريات يومية'!$B$2:$B$4001,'إعدادات المخزون'!$A$16,'مشتريات يومية'!$A$2:$A$4001,'إعدادات المخزون'!$B$4) -> 0 | D24: =SUMIFS('مشتريات يومية'!$E$2:$E$4001,'مشتريات يومية'!$B$2:$B$4001,'إعدادات المخزون'!$A$17,'مشتريات يومية'!$A$2:$A$4001,'إعدادات المخزون'!$B$4) -> 0 | E24: =SUM(B24:D24) -> 0
A25: مشتريات الشهر (جنيه) | B25: =SUMIFS('مشتريات يومية'!$E$2:$E$4001,'مشتريات يومية'!$B$2:$B$4001,'إعدادات المخزون'!$A$15,'مشتريات يومية'!$A$2:$A$4001,">="&'إعدادات المخزون'!$B$5,'مشتريات يومية'!$A$2:$A$4001,"<="&'إعدادات المخزون'!$B$4) -> 174165.05 | C25: =SUMIFS('مشتريات يومية'!$E$2:$E$4001,'مشتريات يومية'!$B$2:$B$4001,'إعدادات المخزون'!$A$16,'مشتريات يومية'!$A$2:$A$4001,">="&'إعدادات المخزون'!$B$5,'مشتريات يومية'!$A$2:$A$4001,"<="&'إعدادات المخزون'!$B$4) -> 146929.8 | D25: =SUMIFS('مشتريات يومية'!$E$2:$E$4001,'مشتريات يومية'!$B$2:$B$4001,'إعدادات المخزون'!$A$17,'مشتريات يومية'!$A$2:$A$4001,">="&'إعدادات المخزون'!$B$5,'مشتريات يومية'!$A$2:$A$4001,"<="&'إعدادات المخزون'!$B$4) -> 167070.68 | E25: =SUM(B25:D25) -> 488165.53
A26: % مشتريات من إيراد الشهر | B26: =IFERROR(B25/B21,0) -> 0.56992163 | C26: =IFERROR(C25/C21,0) -> 0.52783878 | D26: =IFERROR(D25/D21,0) -> 0.53234378 | E26: =IFERROR(E25/E21,0) -> 0.54373788
A29: أكبر 10 عجز (بالقيمة) لكل فرع
A30: فرع محرم بك
A31: المكون | B31: الفرق (كمية) | C31: الوحدة | D31: قيمة العجز (جنيه)
A32: =IF(LARGE('جرد - محرم بك'!$X$7:$X$95,1)<=0,"",INDEX('جرد - محرم بك'!$A$7:$A$95,MATCH(LARGE('جرد - محرم بك'!$X$7:$X$95,1),'جرد - محرم بك'!$X$7:$X$95,0))) | B32: =IF($A32="","",INDEX('جرد - محرم بك'!$M$7:$M$95,MATCH(LARGE('جرد - محرم بك'!$X$7:$X$95,1),'جرد - محرم بك'!$X$7:$X$95,0))) | C32: =IF($A32="","",INDEX('جرد - محرم بك'!$B$7:$B$95,MATCH(LARGE('جرد - محرم بك'!$X$7:$X$95,1),'جرد - محرم بك'!$X$7:$X$95,0))) | D32: =IF($A32="","",INDEX('جرد - محرم بك'!$O$7:$O$95,MATCH(LARGE('جرد - محرم بك'!$X$7:$X$95,1),'جرد - محرم بك'!$X$7:$X$95,0)))
A33: =IF(LARGE('جرد - محرم بك'!$X$7:$X$95,2)<=0,"",INDEX('جرد - محرم بك'!$A$7:$A$95,MATCH(LARGE('جرد - محرم بك'!$X$7:$X$95,2),'جرد - محرم بك'!$X$7:$X$95,0))) | B33: =IF($A33="","",INDEX('جرد - محرم بك'!$M$7:$M$95,MATCH(LARGE('جرد - محرم بك'!$X$7:$X$95,2),'جرد - محرم بك'!$X$7:$X$95,0))) | C33: =IF($A33="","",INDEX('جرد - محرم بك'!$B$7:$B$95,MATCH(LARGE('جرد - محرم بك'!$X$7:$X$95,2),'جرد - محرم بك'!$X$7:$X$95,0))) | D33: =IF($A33="","",INDEX('جرد - محرم بك'!$O$7:$O$95,MATCH(LARGE('جرد - محرم بك'!$X$7:$X$95,2),'جرد - محرم بك'!$X$7:$X$95,0)))
A34: =IF(LARGE('جرد - محرم بك'!$X$7:$X$95,3)<=0,"",INDEX('جرد - محرم بك'!$A$7:$A$95,MATCH(LARGE('جرد - محرم بك'!$X$7:$X$95,3),'جرد - محرم بك'!$X$7:$X$95,0))) | B34: =IF($A34="","",INDEX('جرد - محرم بك'!$M$7:$M$95,MATCH(LARGE('جرد - محرم بك'!$X$7:$X$95,3),'جرد - محرم بك'!$X$7:$X$95,0))) | C34: =IF($A34="","",INDEX('جرد - محرم بك'!$B$7:$B$95,MATCH(LARGE('جرد - محرم بك'!$X$7:$X$95,3),'جرد - محرم بك'!$X$7:$X$95,0))) | D34: =IF($A34="","",INDEX('جرد - محرم بك'!$O$7:$O$95,MATCH(LARGE('جرد - محرم بك'!$X$7:$X$95,3),'جرد - محرم بك'!$X$7:$X$95,0)))
A35: =IF(LARGE('جرد - محرم بك'!$X$7:$X$95,4)<=0,"",INDEX('جرد - محرم بك'!$A$7:$A$95,MATCH(LARGE('جرد - محرم بك'!$X$7:$X$95,4),'جرد - محرم بك'!$X$7:$X$95,0))) | B35: =IF($A35="","",INDEX('جرد - محرم بك'!$M$7:$M$95,MATCH(LARGE('جرد - محرم بك'!$X$7:$X$95,4),'جرد - محرم بك'!$X$7:$X$95,0))) | C35: =IF($A35="","",INDEX('جرد - محرم بك'!$B$7:$B$95,MATCH(LARGE('جرد - محرم بك'!$X$7:$X$95,4),'جرد - محرم بك'!$X$7:$X$95,0))) | D35: =IF($A35="","",INDEX('جرد - محرم بك'!$O$7:$O$95,MATCH(LARGE('جرد - محرم بك'!$X$7:$X$95,4),'جرد - محرم بك'!$X$7:$X$95,0)))
A36: =IF(LARGE('جرد - محرم بك'!$X$7:$X$95,5)<=0,"",INDEX('جرد - محرم بك'!$A$7:$A$95,MATCH(LARGE('جرد - محرم بك'!$X$7:$X$95,5),'جرد - محرم بك'!$X$7:$X$95,0))) | B36: =IF($A36="","",INDEX('جرد - محرم بك'!$M$7:$M$95,MATCH(LARGE('جرد - محرم بك'!$X$7:$X$95,5),'جرد - محرم بك'!$X$7:$X$95,0))) | C36: =IF($A36="","",INDEX('جرد - محرم بك'!$B$7:$B$95,MATCH(LARGE('جرد - محرم بك'!$X$7:$X$95,5),'جرد - محرم بك'!$X$7:$X$95,0))) | D36: =IF($A36="","",INDEX('جرد - محرم بك'!$O$7:$O$95,MATCH(LARGE('جرد - محرم بك'!$X$7:$X$95,5),'جرد - محرم بك'!$X$7:$X$95,0)))
A37: =IF(LARGE('جرد - محرم بك'!$X$7:$X$95,6)<=0,"",INDEX('جرد - محرم بك'!$A$7:$A$95,MATCH(LARGE('جرد - محرم بك'!$X$7:$X$95,6),'جرد - محرم بك'!$X$7:$X$95,0))) | B37: =IF($A37="","",INDEX('جرد - محرم بك'!$M$7:$M$95,MATCH(LARGE('جرد - محرم بك'!$X$7:$X$95,6),'جرد - محرم بك'!$X$7:$X$95,0))) | C37: =IF($A37="","",INDEX('جرد - محرم بك'!$B$7:$B$95,MATCH(LARGE('جرد - محرم بك'!$X$7:$X$95,6),'جرد - محرم بك'!$X$7:$X$95,0))) | D37: =IF($A37="","",INDEX('جرد - محرم بك'!$O$7:$O$95,MATCH(LARGE('جرد - محرم بك'!$X$7:$X$95,6),'جرد - محرم بك'!$X$7:$X$95,0)))
A38: =IF(LARGE('جرد - محرم بك'!$X$7:$X$95,7)<=0,"",INDEX('جرد - محرم بك'!$A$7:$A$95,MATCH(LARGE('جرد - محرم بك'!$X$7:$X$95,7),'جرد - محرم بك'!$X$7:$X$95,0))) | B38: =IF($A38="","",INDEX('جرد - محرم بك'!$M$7:$M$95,MATCH(LARGE('جرد - محرم بك'!$X$7:$X$95,7),'جرد - محرم بك'!$X$7:$X$95,0))) | C38: =IF($A38="","",INDEX('جرد - محرم بك'!$B$7:$B$95,MATCH(LARGE('جرد - محرم بك'!$X$7:$X$95,7),'جرد - محرم بك'!$X$7:$X$95,0))) | D38: =IF($A38="","",INDEX('جرد - محرم بك'!$O$7:$O$95,MATCH(LARGE('جرد - محرم بك'!$X$7:$X$95,7),'جرد - محرم بك'!$X$7:$X$95,0)))
A39: =IF(LARGE('جرد - محرم بك'!$X$7:$X$95,8)<=0,"",INDEX('جرد - محرم بك'!$A$7:$A$95,MATCH(LARGE('جرد - محرم بك'!$X$7:$X$95,8),'جرد - محرم بك'!$X$7:$X$95,0))) | B39: =IF($A39="","",INDEX('جرد - محرم بك'!$M$7:$M$95,MATCH(LARGE('جرد - محرم بك'!$X$7:$X$95,8),'جرد - محرم بك'!$X$7:$X$95,0))) | C39: =IF($A39="","",INDEX('جرد - محرم بك'!$B$7:$B$95,MATCH(LARGE('جرد - محرم بك'!$X$7:$X$95,8),'جرد - محرم بك'!$X$7:$X$95,0))) | D39: =IF($A39="","",INDEX('جرد - محرم بك'!$O$7:$O$95,MATCH(LARGE('جرد - محرم بك'!$X$7:$X$95,8),'جرد - محرم بك'!$X$7:$X$95,0)))
A40: =IF(LARGE('جرد - محرم بك'!$X$7:$X$95,9)<=0,"",INDEX('جرد - محرم بك'!$A$7:$A$95,MATCH(LARGE('جرد - محرم بك'!$X$7:$X$95,9),'جرد - محرم بك'!$X$7:$X$95,0))) | B40: =IF($A40="","",INDEX('جرد - محرم بك'!$M$7:$M$95,MATCH(LARGE('جرد - محرم بك'!$X$7:$X$95,9),'جرد - محرم بك'!$X$7:$X$95,0))) | C40: =IF($A40="","",INDEX('جرد - محرم بك'!$B$7:$B$95,MATCH(LARGE('جرد - محرم بك'!$X$7:$X$95,9),'جرد - محرم بك'!$X$7:$X$95,0))) | D40: =IF($A40="","",INDEX('جرد - محرم بك'!$O$7:$O$95,MATCH(LARGE('جرد - محرم بك'!$X$7:$X$95,9),'جرد - محرم بك'!$X$7:$X$95,0)))
A41: =IF(LARGE('جرد - محرم بك'!$X$7:$X$95,10)<=0,"",INDEX('جرد - محرم بك'!$A$7:$A$95,MATCH(LARGE('جرد - محرم بك'!$X$7:$X$95,10),'جرد - محرم بك'!$X$7:$X$95,0))) | B41: =IF($A41="","",INDEX('جرد - محرم بك'!$M$7:$M$95,MATCH(LARGE('جرد - محرم بك'!$X$7:$X$95,10),'جرد - محرم بك'!$X$7:$X$95,0))) | C41: =IF($A41="","",INDEX('جرد - محرم بك'!$B$7:$B$95,MATCH(LARGE('جرد - محرم بك'!$X$7:$X$95,10),'جرد - محرم بك'!$X$7:$X$95,0))) | D41: =IF($A41="","",INDEX('جرد - محرم بك'!$O$7:$O$95,MATCH(LARGE('جرد - محرم بك'!$X$7:$X$95,10),'جرد - محرم بك'!$X$7:$X$95,0)))
A43: فرع ابراهيمية
A44: المكون | B44: الفرق (كمية) | C44: الوحدة | D44: قيمة العجز (جنيه)
...

Sheet دليل الجرد
A1: دليل استخدام الجرد والمخزون
A3: الخطوة | B3: التفاصيل
A4: الفكرة | B4: الدفتري = جرد أول المدة + المشتريات + التحويلات - الاستهلاك النظري (مبيعات الأصناف × الريسبي) - الهالك. الفرق = الجرد الفعلي - الدفتري. سالب = عجز، موجب = زيادة. الفرق تراكمي من بداية الشهر.
A5: كل يوم 1: المبيعات | B5: في شيت "مبيعات يومية": سطر لكل (تاريخ، فرع، صنف) بالكمية المباعة. اسم الصنف من القايمة المنسدلة (نفس أسماء المنيو). مثال: 2026-10-13 | محرم بك | بيتزا مارجريتا وسط | 24.
A6: كل يوم 2: المشتريات | B6: في "مشتريات يومية": التاريخ، الفرع، المكون، الكمية بوحدة الجرد، القيمة. مثال: 2026-10-13 | ابراهيمية | عجين بيتزا | 40 | 880. (مشتريات 1-12 أكتوبر محمّلة تجميعي من تقارير الكاشير على تاريخ 2026-10-01.)
A7: كل يوم 3: الجرد الفعلي | B7: في "جرد فعلي": الكمية اللي عدّيتوها فعلاً آخر اليوم لكل مكون. مثال: 2026-10-13 | عصافرة | طماطم | 12.5. اللي ما اتجردش بيظهر "لم يُجرد".
A8: كل يوم 4: الهالك والتحويل | B8: في "هالك وتحويلات": الهالك والضيافة وأكل الموظفين والتحويلات بين الفروع والسنتر. تحويل صادر من فرع لازم يتسجل تحويل وارد للفرع التاني.
A9: كل يوم 5: التقرير | B9: غيّر "تاريخ التقرير" في "إعدادات المخزون" لليوم، وشوف شيتات "جرد - اسم الفرع" والداشبورد وطلبية السنتر.
A10: الطلبية المقترحة | B10: بتتحسب من متوسط استهلاك آخر 7 أيام (أو من بداية الفترة) × أيام التغطية والتوريد والأمان - المخزون الحالي. أيام التغطية وحجم العبوة من الإعدادات.
A11: مهم | B11: مبيعات أكتوبر من 1 لحد اليوم لازم تتسجل علشان الدفتري يطلع صح، وإلا الدفتري هيبقى أعلى من الفعلي ويظهر عجز كبير غير حقيقي.
A12: حدود الشيت | B12: الجداول بتستوعب ~14000 سطر مبيعات، ~4000 مشتريات، ~12000 جرد فعلي، ~3000 هالك. الأعمدة المحسوبة (سعر، إيراد، تكلفة) جاهزة. مبيعات 1-12 أكتوبر محمّلة تجميعي من تقارير الكاشير (عادي + طلبات) وموزعة بالتساوي على الأيام، فاستبدلها بالمبيعات اليومية الفعلية لما تتوفر.
A13: خارج الجرد | B13: مواد التنظيف والمكتبية والزيت مش مرتبطة بالمبيعات فمش في الجرد. المكونات المصنّعة جوه المطعم (كاسترد، عجين كريب) استهلاكها بيتحسب على خاماتها.

Sheet التعليمات
A1: دليل استخدام شيت تكلفة المنيو - Satamoni
A3: ترتيب الشيتات | B3: المكونات ← المنيو ← الريسبي ← تحليل التكلفة والسعر ← تكلفة العروض
A4: 1. شيت المكونات | B4: اكتب فيه كل مكون بتشتريه (دقيق، جبنة، صوص...) مع وحدة القياس وسعر الوحدة. أي مكون مش موجود هنا مش هيتحسب في أي ريسبي.
A5: 2. شيت المنيو | B5: اكتب فيه كل صنف في المنيو مع تصنيفه وسعر بيعه الحالي. اسم الصنف هنا هو المفتاح اللي هيتربط بيه كل حاجة، فاكتبه بالظبط زي ما هيتكرر في شيت الريسبي.
A6: 3. شيت الريسبي | B6: لكل صنف، اكتب سطر منفصل لكل مكون داخل في الريسبي بتاعه مع الكمية المستخدمة. تكلفة الوحدة والوحدة بيتجابوا أوتوماتيك من شيت المكونات.
A7: 4. شيت تحليل التكلفة والسعر | B7: بيتجمع فيه تلقائيًا تكلفة كل صنف من شيت الريسبي، ويحسب نسبة تكلفة الطعام، والسعر العادل لتحقيق النسبة المستهدفة اللي بتحددها.
A8: 5. شيت تكلفة العروض | B8: لعمل عرض (كومبو) بيضم أكتر من صنف، اختار اسم العرض والأصناف الداخلة فيه وكميتها، والشيت هيحسب تكلفة العرض كامل ونسبة تكلفته من سعر البيع المقترح.
A9: الألوان | B9: أصفر = خانة لازم تملاها انت. أزرق = رقم مدخل يدوي. أخضر = رابط جاي من شيت تاني. أسود = معادلة تلقائية، متلمسهاش.
A10: النسبة المستهدفة | B10: الافتراضي متحطوط 37.5% (نص المدى اللي حددته 35%-40%) في خلية صفراء بشيت تحليل التكلفة، وتقدر تغيره في أي وقت.
A11: مهم | B11: متغيرش اسم أي صنف أو مكون في شيت وبس - غيره في كل الشيتات اللي اتكرر فيها، لأن الربط بيتم بالاسم بالظبط (حروف كبيرة/صغيرة ومسافات فارقة).
A13: نسخة أكتوبر 2026 | B13: اتحدثت أسعار الخامات في شيت المكونات من تقارير الكاشير (مشتريات 1-12 أكتوبر + جرد 30 سبتمبر). شوف شيت "تغيّر الأسعار" للمقارنة مع يوليو، و"تأثير الأسعار على الأصناف" لأثرها على تكلفة كل صنف. أسعار البيع في المنيو = أسعار يوليو + 10 جنيه لكل صنف (ما عدا عيش كريب وبيبسي لتر: فضلوا على سعر يوليو). اتضافت 18 صنف جديد آخر المنيو (فطيرة نوتيلا، مكرونة مفروم، كريب جمبري، كريب فراخ جريل، وجبات الأطفال، وإضافات ومشروبات) بريسبي مقترح من أصناف مشابهة وسعر من تقارير المبيعات: راجعهم. واتضاف 3 مكونات جديدة (عصير، بيبسي 2 لتر، مياه معدنية صغير).

Sheet المكونات
A1: اسم المكون | B1: وحدة القياس | C1: تكلفة الوحدة (جنيه) | D1: ملاحظات | E1: كود الصنف (من نظام الكاشير) | F1: تاريخ آخر تحديث للسعر
A2: اطباق سيلفر مكرونة | B2: قطعة | C2: 3.3 | D2: [أكتوبر 2026] مشتريات 1-12 أكتوبر (يوليو: 3.3). من تقرير مشتريات فرع محرم بك (1-28 يوليو 2026): تكلفة الوحدة = صافي القيمة ÷ صافي الكمية | E2: 1823 | F2: 46307
A3: اطباق فوم كيلو | B3: قطعة | C3: 0.8 | D3: [أكتوبر 2026] مشتريات 1-12 أكتوبر (يوليو: 0.7). الوحدة تخمين من اسم الصنف - يُرجى التأكيد | E3: 1814 | F3: 46307
A4: اطباق فوم نص كيلو | B4: قطعة | C4: 0.5 | D4: [أكتوبر 2026] مشتريات 1-12 أكتوبر (يوليو: 0.5). الوحدة تخمين من اسم الصنف - يُرجى التأكيد | E4: 1815 | F4: 46307
A5: اكياس بيضاء | B5: قطعة | C5: 150 | D5: [أكتوبر 2026] مشتريات 1-12 أكتوبر (يوليو: 120). الوحدة تخمين من اسم الصنف - يُرجى التأكيد | E5: 2291 | F5: 46307
A6: اكياس قمامة | B6: قطعة | C6: 80 | D6: [أكتوبر 2026] مشتريات 1-12 أكتوبر (يوليو: 74.29). الوحدة تخمين من اسم الصنف - يُرجى التأكيد | E6: 2280 | F6: 46307
A7: اكياس مطبوعة كبير | B7: قطعة (كيس) | C7: 1.4 | D7: [أكتوبر 2026] مشتريات 1-12 أكتوبر (يوليو: 1.523). 1 كجم ≈ 50 كيس - حسب تأكيد صاحب الملف | E7: 1828 | F7: 46307
A8: اكياس مطبوعة وسط | B8: قطعة (كيس) | C8: 1.4 | D8: [أكتوبر 2026] مشتريات 1-12 أكتوبر (يوليو: 1.6). 1 كجم ≈ 50 كيس - حسب تأكيد صاحب الملف (نفس نسبة الكبير) | E8: 1827 | F8: 46307
A9: اوفر هيد | B9: قطعة | C9: 60 | D9: [أكتوبر 2026] مشتريات 1-12 أكتوبر (يوليو: 60). الوحدة تخمين من اسم الصنف - يُرجى التأكيد | E9: 2275 | F9: 46307
A10: برجر 100 جرام | B10: قطعة | C10: 18 | D10: [أكتوبر 2026] مشتريات 1-12 أكتوبر (يوليو: 18.76). الوحدة تخمين من اسم الصنف - يُرجى التأكيد | E10: 2215 | F10: 46307
A11: برسيون بسطرمة صغير | B11: قطعة | C11: 35 | D11: [أكتوبر 2026] مشتريات 1-12 أكتوبر (يوليو: 33.5). تم تأكيد الوحدة (قطعة) من صاحب الملف | E11: 1748 | F11: 46307
A12: برسيون بسطرمة كبير | B12: قطعة | C12: 46.6667 | D12: [أكتوبر 2026] مشتريات 1-12 أكتوبر (يوليو: 43). تم تأكيد الوحدة (قطعة) من صاحب الملف | E12: 2581 | F12: 46307
A13: برسيون بطاطس | B13: قطعة | C13: 5.65 | D13: [أكتوبر 2026] مشتريات 1-12 أكتوبر (يوليو: 5.5). تم تأكيد الوحدة (قطعة) من صاحب الملف | E13: 2344 | F13: 46307
... A101: ورق زبدة وسط كيلو 500 ورقة | B101: قطعة (ورقة) | C101: 0.3665 | D101: [أكتوبر 2026] متوسط تكلفة جرد 30-9 (يوليو: 0.28). 1 كجم ≈ 100-150 ورقة (متوسط 125) - حسب تأكيد صاحب الملف | E101: 1812 | F101: 46307
A102: اكياس كفرات | B102: قطعة (كيس) | C102: 1 | D102: [أكتوبر 2026] مشتريات 1-12 أكتوبر (يوليو: 0.65). أضيف يدويًا: 130 جنيه/كجم، 1 كجم ≈ 200 كيس - بيانات من صاحب الملف | E102: جديد | F102: 46307
A103: كاسترد مصنع (خليط بودر + لبن) | B103: كجم | C103: =IFERROR((850/5000)*INDEX($C$2:$C$500,MATCH("كاستر بودر",$A$2:$A$500,0))+(2000/5000)*INDEX($C$2:$C$500,MATCH("لبن",$A$2:$A$500,0)),"") -> 23.56668 | D103: مكون مركب: 850 جم كاستر بودر + 2 كيلو لبن ⇐ 5 كيلو كاسترد نهائي (حسب صاحب الملف). التكلفة بتتحسب أوتوماتيك من أسعار كاستر بودر ولبن أعلاه. | E103: مركب | F103: 46230
A104: علبة كاليزوني | B104: قطعة | C104: 4.47 | D104: [أكتوبر 2026] متوسط تكلفة جرد 30-9 (يوليو: 4.4). مسمى مكرر/خطأ في نظام الكاشير - دي نفس "علب مكرونة" (كود 1820) فعليًا حسب تأكيد صاحب الملف. مش مستخدمة في أي ريسبي حاليًا. | E104: 1819 | F104: 46307
A105: عجين كريب (مصنع بالمطعم) | B105: قطعة | C105: =IFERROR((2*INDEX($C$2:$C$500,MATCH("لبن",$A$2:$A$500,0))+0.25*INDEX($C$2:$C$500,MATCH("زبدة",$A$2:$A$500,0))+5*INDEX($C$2:$C$500,MATCH("دقيق",$A$2:$A$500,0))+0.25*INDEX($C$2:$C$500,MATCH("سكر بودرة",$A$2:$A$500,0)))/60,"") -> 3.0130621 | D105: مكون مركب: 2 كيلو لبن + 250 جم زبدة + 5 كيلو دقيق + 250 جم سكر بودرة ⇐ 60 عجينة كريب (حسب صاحب الملف). التكلفة بتتحسب أوتوماتيك من أسعار لبن/زبدة/دقيق/سكر بودرة أعلاه. | E105: مركب | F105: 46230
A106: كاسترد مصنع صيامي (بدون لبن) | B106: كجم | C106: =IFERROR((850/5000)*INDEX($C$2:$C$500,MATCH("كاستر بودر",$A$2:$A$500,0)),"") -> 15.3 | D106: نسخة صيامي من الكاسترد: نفس التركيبة بدون اللبن (اتعوض بمية بدون تكلفة تذكر حسب صاحب الملف). | E106: مركب | F106: 46230
A107: عجين كريب صيامي (بدون لبن) | B107: قطعة | C107: =IFERROR((0.25*INDEX($C$2:$C$500,MATCH("زبدة",$A$2:$A$500,0))+5*INDEX($C$2:$C$500,MATCH("دقيق",$A$2:$A$500,0))+0.25*INDEX($C$2:$C$500,MATCH("سكر بودرة",$A$2:$A$500,0)))/60,"") -> 2.3241721 | D107: نسخة صيامي من عجين الكريب: نفس التركيبة بدون اللبن (اتعوض بمية بدون تكلفة تذكر حسب صاحب الملف). | E107: مركب | F107: 46230
A108: سوسيس/سدق صيامي | B108: كجم | C108: 220.02 | D108: [أكتوبر 2026] متوسط تكلفة جرد 30-9 (يوليو: 220). أضيف يدويًا: كود 2232، 220 جنيه/كجم - بيانات من صاحب الملف | E108: 2232 | F108: 46307
A109: شاورما فراخ/سدق صيامي | B109: كجم | C109: 219.23 | D109: [أكتوبر 2026] متوسط تكلفة جرد 30-9 (يوليو: 220). أضيف يدويًا: كود 2234، 220 جنيه/كجم - بيانات من صاحب الملف | E109: 2234 | F109: 46307
A110: برجر صيامي | B110: قطعة | C110: 6 | D110: [أكتوبر 2026] متوسط تكلفة جرد 30-9 (يوليو: 6). أضيف يدويًا: كود 2236، 6 جنيه/قطعة - بيانات من صاحب الملف | E110: 2236 | F110: 46307
A111: سكينة بلاستيك | B111: قطعة | C111: 0.3 | D111: [أكتوبر 2026] مشتريات 1-12 أكتوبر (يوليو: 0.3). نفس سعر شوك بلاستيك (0.3 جنيه/قطعة) - حسب تأكيد صاحب الملف. كود 1825 من تقرير الجرد. | E111: 1825 | F111: 46307
A112: علب مكرونة | B112: قطعة | C112: 4.44 | D112: [أكتوبر 2026] متوسط تكلفة جرد 30-9 (يوليو: 4.4). كود 1820، 4.40 جنيه - من تقرير الجرد. الصح للمكرونة والبرجر (كانت متسجلة غلط باسم كاليزوني/بلاستيك وجبات). | E112: 1820 | F112: 46307
A113: علب بيتزا كيك | B113: قطعة | C113: 8 | D113: [أكتوبر 2026] مشتريات 1-12 أكتوبر (يوليو: 35). كود 1821، 35 جنيه - من تقرير الجرد. مستخدمة في شيكاغو بيتزا برجر حسب ريسبي الكاشير. | E113: 1821 | F113: 46307
A114: تكلفة زيت القلي المخصصة للوحدة | B114: قطعة | C114: 5.5777 | D114: تكلفة مخصصة لزيت اولين (القلاية) موزعة على الأصناف اللي بتتقلى بس. الحساب: إجمالي شراء زيت اولين الشهر (1,400 جنيه لـ20 لتر، من تقرير مشتريات يوليو الكامل) ÷ إجمالي مبيعات الأصناف اللي بتتقلى (كريسبي + بطاطس، 251 وحدة في يوليو) ≈ 5.58 جنيه/وحدة. بتتضاف كسطر ريسبي منفصل لكل صنف بيتقلى بس، مش كل المنيو. | E114: جديد | F114: 46230
A115: عصير | B115: قطعة | C115: 7 | D115: [أكتوبر 2026] عصير وجبات الأطفال: تكلفة تقريبية 7 جنيه حسب صاحب الملف | E115: جديد | F115: 46307
A116: بيبسي 2 لتر | B116: قطعة | C116: 40 | D116: [أكتوبر 2026] كود 1723: سعر الجرد 40 (فرع عصافرة) ومشتريات 45. تقريبي - راجعه | E116: جديد | F116: 46307
A117: مياة معدنية صغير | B117: قطعة | C117: 7 | D117: [أكتوبر 2026] كود 2252: من جرد 30-9 (7 جنيه) | E117: جديد | F117: 46307

Sheet تغيّر الأسعار
A1: تغيّر أسعار الخامات: يوليو 2026 ← أكتوبر 2026
A2: مصدر أكتوبر: تقارير المشتريات (1-12 أكتوبر، فرعين) وتقارير الجرد المقيّم بمتوسط التكلفة (30 سبتمبر، 3 فروع). سعر أكتوبر هنا مربوط بشيت المكونات (لو عدلته هناك يتحدث هنا). الخلايا المظللة بالأصفر في المكونات = تغير أكبر من 20% محتاج تأكيد.
A4: المكون | B4: الوحدة | C4: سعر يوليو (جنيه) | D4: سعر أكتوبر (جنيه) | E4: الفرق (جنيه) | F4: % التغير | G4: مصدر سعر أكتوبر | H4: سعر الوحدة في تقرير الكاشير | I4: معامل التحويل | J4: يحتاج مراجعة؟
A5: علب بيتزا كيك | B5: قطعة | C5: 35 | D5: =INDEX(المكونات!$C$2:$C$500,MATCH($A5,المكونات!$A$2:$A$500,0)) -> 8 | E5: =D5-C5 -> -27 | F5: =IF(C5=0,"",D5/C5-1) -> -0.77142857 | G5: مشتريات 1-12 أكتوبر | H5: 8 | I5: 1 | J5: ⚠ تغير >20% — اتأكد
A6: اكياس كفرات | B6: قطعة (كيس) | C6: 0.65 | D6: =INDEX(المكونات!$C$2:$C$500,MATCH($A6,المكونات!$A$2:$A$500,0)) -> 1 | E6: =D6-C6 -> 0.35 | F6: =IF(C6=0,"",D6/C6-1) -> 0.53846154 | G6: مشتريات 1-12 أكتوبر | H6: 200 | I6: 200 | J6: ⚠ تغير >20% — اتأكد
A7: فوط يد | B7: قطعة | C7: 10 | D7: =INDEX(المكونات!$C$2:$C$500,MATCH($A7,المكونات!$A$2:$A$500,0)) -> 15 | E7: =D7-C7 -> 5 | F7: =IF(C7=0,"",D7/C7-1) -> 0.5 | G7: متوسط تكلفة جرد 30-9 | H7: 15 | I7: 1 | J7: ⚠ تغير >20% — اتأكد
A8: مشروم فريش | B8: كجم | C8: 233.33 | D8: =INDEX(المكونات!$C$2:$C$500,MATCH($A8,المكونات!$A$2:$A$500,0)) -> 151.2027 | E8: =D8-C8 -> -82.1273 | F8: =IF(C8=0,"",D8/C8-1) -> -0.35197917 | G8: مشتريات 1-12 أكتوبر | H8: 151.2027 | I8: 1 | J8: ⚠ تغير >20% — اتأكد
A9: برسيون فراخ كريسبي كبير | B9: قطعة | C9: 44 | D9: =INDEX(المكونات!$C$2:$C$500,MATCH($A9,المكونات!$A$2:$A$500,0)) -> 29 | E9: =D9-C9 -> -15 | F9: =IF(C9=0,"",D9/C9-1) -> -0.34090909 | G9: مشتريات 1-12 أكتوبر | H9: 29 | I9: 1 | J9: ⚠ تغير >20% — اتأكد
A10: ورق زبدة وسط كيلو 500 ورقة | B10: قطعة (ورقة) | C10: 0.28 | D10: =INDEX(المكونات!$C$2:$C$500,MATCH($A10,المكونات!$A$2:$A$500,0)) -> 0.3665 | E10: =D10-C10 -> 0.0865 | F10: =IF(C10=0,"",D10/C10-1) -> 0.30892857 | G10: متوسط تكلفة جرد 30-9 | H10: 120 | I10: 125 | J10: ⚠ تغير >20% — اتأكد
A11: بصل | B11: كجم | C11: 14 | D11: =INDEX(المكونات!$C$2:$C$500,MATCH($A11,المكونات!$A$2:$A$500,0)) -> 18 | E11: =D11-C11 -> 4 | F11: =IF(C11=0,"",D11/C11-1) -> 0.28571429 | G11: مشتريات 1-12 أكتوبر | H11: 18 | I11: 1 | J11: ⚠ تغير >20% — اتأكد
A12: اكياس بيضاء | B12: قطعة | C12: 120 | D12: =INDEX(المكونات!$C$2:$C$500,MATCH($A12,المكونات!$A$2:$A$500,0)) -> 150 | E12: =D12-C12 -> 30 | F12: =IF(C12=0,"",D12/C12-1) -> 0.25 | G12: مشتريات 1-12 أكتوبر | H12: 150 | I12: 1 | J12: ⚠ تغير >20% — اتأكد
A13: زيتون | B13: كجم | C13: 125 | D13: =INDEX(المكونات!$C$2:$C$500,MATCH($A13,المكونات!$A$2:$A$500,0)) -> 95 | E13: =D13-C13 -> -30 | F13: =IF(C13=0,"",D13/C13-1) -> -0.24 | G13: مشتريات 1-12 أكتوبر | H13: 95 | I13: 1 | J13: ⚠ تغير >20% — اتأكد
A14: بكر استريتش | B14: قطعة (لفة استخدام) | C14: 2.95 | D14: =INDEX(المكونات!$C$2:$C$500,MATCH($A14,المكونات!$A$2:$A$500,0)) -> 3.65 | E14: =D14-C14 -> 0.7 | F14: =IF(C14=0,"",D14/C14-1) -> 0.23728814 | G14: مشتريات 1-12 أكتوبر | H14: 730 | I14: 200 | J14: ⚠ تغير >20% — اتأكد
A15: شيكولاتة بني | B15: كجم | C15: 110 | D15: =INDEX(المكونات!$C$2:$C$500,MATCH($A15,المكونات!$A$2:$A$500,0)) -> 127.6582 | E15: =D15-C15 -> 17.6582 | F15: =IF(C15=0,"",D15/C15-1) -> 0.16052909 | G15: مشتريات 1-12 أكتوبر | H15: 127.6582 | I15: 1
A16: عجين بيتزا | B16: كجم | C16: 19 | D16: =INDEX(المكونات!$C$2:$C$500,MATCH($A16,المكونات!$A$2:$A$500,0)) -> 22 | E16: =D16-C16 -> 3 | F16: =IF(C16=0,"",D16/C16-1) -> 0.15789474 | G16: مشتريات 1-12 أكتوبر | H16: 22 | I16: 1
A17: شطة | B17: كجم | C17: 95 | D17: =INDEX(المكونات!$C$2:$C$500,MATCH($A17,المكونات!$A$2:$A$500,0)) -> 109.9656 | E17: =D17-C17 -> 14.9656 | F17: =IF(C17=0,"",D17/C17-1) -> 0.15753263 | G17: مشتريات 1-12 أكتوبر | H17: 109.9656 | I17: 1
A18: فراخ كريسبي صيامي | B18: كجم | C18: 130 | D18: =INDEX(المكونات!$C$2:$C$500,MATCH($A18,المكونات!$A$2:$A$500,0)) -> 150 | E18: =D18-C18 -> 20 | F18: =IF(C18=0,"",D18/C18-1) -> 0.15384615 | G18: متوسط تكلفة جرد 30-9 | H18: 150 | I18: 1
A19: بيبسي كانز | B19: قطعة | C19: 15 | D19: =INDEX(المكونات!$C$2:$C$500,MATCH($A19,المكونات!$A$2:$A$500,0)) -> 17.1875 | E19: =D19-C19 -> 2.1875 | F19: =IF(C19=0,"",D19/C19-1) -> 0.14583333 | G19: مشتريات 1-12 أكتوبر | H19: 17.1875 | I19: 1
A20: اطباق فوم كيلو | B20: قطعة | C20: 0.7 | D20: =INDEX(المكونات!$C$2:$C$500,MATCH($A20,المكونات!$A$2:$A$500,0)) -> 0.8 | E20: =D20-C20 -> 0.1 | F20: =IF(C20=0,"",D20/C20-1) -> 0.14285714 | G20: مشتريات 1-12 أكتوبر | H20: 0.8 | I20: 1
A21: بيبسي لتر | B21: لتر | C21: 35 | D21: =INDEX(المكونات!$C$2:$C$500,MATCH($A21,المكونات!$A$2:$A$500,0)) -> 30 | E21: =D21-C21 -> -5 | F21: =IF(C21=0,"",D21/C21-1) -> -0.14285714 | G21: مشتريات 1-12 أكتوبر | H21: 30 | I21: 1
A22: برسيون قشطة | B22: قطعة | C22: 22 | D22: =INDEX(المكونات!$C$2:$C$500,MATCH($A22,المكونات!$A$2:$A$500,0)) -> 25 | E22: =D22-C22 -> 3 | F22: =IF(C22=0,"",D22/C22-1) -> 0.13636364 | G22: مشتريات 1-12 أكتوبر | H22: 25 | I22: 1
A23: دقيق | B23: كجم | C23: 18 | D23: =INDEX(المكونات!$C$2:$C$500,MATCH($A23,المكونات!$A$2:$A$500,0)) -> 20.3571 | E23: =D23-C23 -> 2.3571 | F23: =IF(C23=0,"",D23/C23-1) -> 0.13095 | G23: مشتريات 1-12 أكتوبر | H23: 20.3571 | I23: 1
A24: اكياس مطبوعة وسط | B24: قطعة (كيس) | C24: 1.6 | D24: =INDEX(المكونات!$C$2:$C$500,MATCH($A24,المكونات!$A$2:$A$500,0)) -> 1.4 | E24: =D24-C24 -> -0.2 | F24: =IF(C24=0,"",D24/C24-1) -> -0.125 | G24: مشتريات 1-12 أكتوبر | H24: 70 | I24: 50
A25: جلافزات شفاف | B25: قطعة (جلفز) | C25: 0.16 | D25: =INDEX(المكونات!$C$2:$C$500,MATCH($A25,المكونات!$A$2:$A$500,0)) -> 0.18 | E25: =D25-C25 -> 0.02 | F25: =IF(C25=0,"",D25/C25-1) -> 0.125 | G25: مشتريات 1-12 أكتوبر | H25: 9 | I25: 50
A26: جلافزات سوداء | B26: علبة | C26: 165 | D26: =INDEX(المكونات!$C$2:$C$500,MATCH($A26,المكونات!$A$2:$A$500,0)) -> 181.9048 | E26: =D26-C26 -> 16.9048 | F26: =IF(C26=0,"",D26/C26-1) -> 0.10245333 | G26: مشتريات 1-12 أكتوبر | H26: 181.9048 | I26: 1
... A110: سكينة بلاستيك | B110: قطعة | C110: 0.3 | D110: =INDEX(المكونات!$C$2:$C$500,MATCH($A110,المكونات!$A$2:$A$500,0)) -> 0.3 | E110: =D110-C110 -> 0 | F110: =IF(C110=0,"",D110/C110-1) -> 0 | G110: مشتريات 1-12 أكتوبر | H110: 0.3 | I110: 1
A111: بشاميل مصنع صيامي | B111: كجم | C111: 25 | D111: =INDEX(المكونات!$C$2:$C$500,MATCH($A111,المكونات!$A$2:$A$500,0)) -> 25 | E111: =D111-C111 -> 0 | F111: =IF(C111=0,"",D111/C111-1) -> 0 | G111: لم يتحدث (غير موجود في التقارير) — السعر القديم | I111: 1 | J111: ⚠ بدون تحديث — ابعت السعر
A112: جبنة رومي/شيدر صيامي | B112: كجم | C112: 105 | D112: =INDEX(المكونات!$C$2:$C$500,MATCH($A112,المكونات!$A$2:$A$500,0)) -> 105 | E112: =D112-C112 -> 0 | F112: =IF(C112=0,"",D112/C112-1) -> 0 | G112: لم يتحدث (غير موجود في التقارير) — السعر القديم | I112: 1 | J112: ⚠ بدون تحديث — ابعت السعر
A113: تكلفة زيت القلي المخصصة للوحدة | B113: قطعة | C113: 5.5777 | D113: =INDEX(المكونات!$C$2:$C$500,MATCH($A113,المكونات!$A$2:$A$500,0)) -> 5.5777 | E113: =D113-C113 -> 0 | F113: =IF(C113=0,"",D113/C113-1) -> 0 | G113: لم يتحدث (غير موجود في التقارير) — السعر القديم | I113: 1 | J113: ⚠ بدون تحديث — ابعت السعر

Sheet تأثير الأسعار على الأصناف
A1: تأثير أسعار أكتوبر على تكلفة الأصناف (مع زيادة أسعار البيع 10 جنيه)
A2: تكلفة يوليو أرقام ثابتة من النسخة القديمة. تكلفة أكتوبر مربوطة بشيت تحليل التكلفة. مرتّب بالأكثر تأثرًا.
A4: القسم | B4: اسم الصنف | C4: تكلفة الريسبي - يوليو | D4: تكلفة الريسبي - أكتوبر | E4: الفرق (جنيه) | F4: % التغير | G4: سعر البيع - يوليو | H4: سعر البيع - أكتوبر | I4: % تكلفة الطعام - يوليو | J4: % تكلفة الطعام - أكتوبر | K4: الفرق بالنقاط
A5: قسم الإضافات | B5: اضافة مشروم (بيتزا وسط) | C5: 13.9998 | D5: =INDEX('تحليل التكلفة والسعر'!$C$2:$C$700,MATCH($B5,'تحليل التكلفة والسعر'!$B$2:$B$700,0)) -> 9.072162 | E5: =D5-C5 -> -4.927638 | F5: =IF(C5=0,"",D5/C5-1) -> -0.35197917 | G5: 30 | H5: =INDEX('تحليل التكلفة والسعر'!$D$2:$D$700,MATCH($B5,'تحليل التكلفة والسعر'!$B$2:$B$700,0)) -> 40 | I5: =IF(OR(G5="",G5=0),"",C5/G5) -> 0.46666 | J5: =IF(OR(H5="",H5=0),"",D5/H5) -> 0.22680405 | K5: =IF(OR(I5="",J5=""),"",J5-I5) -> -0.23985595
A6: قسم الإضافات | B6: اضافة مشروم (بيتزا كبير) | C6: 20.9997 | D6: =INDEX('تحليل التكلفة والسعر'!$C$2:$C$700,MATCH($B6,'تحليل التكلفة والسعر'!$B$2:$B$700,0)) -> 13.608243 | E6: =D6-C6 -> -7.391457 | F6: =IF(C6=0,"",D6/C6-1) -> -0.35197917 | G6: 45 | H6: =INDEX('تحليل التكلفة والسعر'!$D$2:$D$700,MATCH($B6,'تحليل التكلفة والسعر'!$B$2:$B$700,0)) -> 55 | I6: =IF(OR(G6="",G6=0),"",C6/G6) -> 0.46666 | J6: =IF(OR(H6="",H6=0),"",D6/H6) -> 0.2474226 | K6: =IF(OR(I6="",J6=""),"",J6-I6) -> -0.2192374
A7: قسم الإضافات | B7: اضافة مشروم (فطير وسط) | C7: 13.9998 | D7: =INDEX('تحليل التكلفة والسعر'!$C$2:$C$700,MATCH($B7,'تحليل التكلفة والسعر'!$B$2:$B$700,0)) -> 9.072162 | E7: =D7-C7 -> -4.927638 | F7: =IF(C7=0,"",D7/C7-1) -> -0.35197917 | G7: 30 | H7: =INDEX('تحليل التكلفة والسعر'!$D$2:$D$700,MATCH($B7,'تحليل التكلفة والسعر'!$B$2:$B$700,0)) -> 40 | I7: =IF(OR(G7="",G7=0),"",C7/G7) -> 0.46666 | J7: =IF(OR(H7="",H7=0),"",D7/H7) -> 0.22680405 | K7: =IF(OR(I7="",J7=""),"",J7-I7) -> -0.23985595
A8: قسم الإضافات | B8: اضافة مشروم (فطير كبير) | C8: 20.9997 | D8: =INDEX('تحليل التكلفة والسعر'!$C$2:$C$700,MATCH($B8,'تحليل التكلفة والسعر'!$B$2:$B$700,0)) -> 13.608243 | E8: =D8-C8 -> -7.391457 | F8: =IF(C8=0,"",D8/C8-1) -> -0.35197917 | G8: 45 | H8: =INDEX('تحليل التكلفة والسعر'!$D$2:$D$700,MATCH($B8,'تحليل التكلفة والسعر'!$B$2:$B$700,0)) -> 55 | I8: =IF(OR(G8="",G8=0),"",C8/G8) -> 0.46666 | J8: =IF(OR(H8="",H8=0),"",D8/H8) -> 0.2474226 | K8: =IF(OR(I8="",J8=""),"",J8-I8) -> -0.2192374
A9: قسم الإضافات | B9: اضافة فراخ كريسبي (فطير كبير) | C9: 44 | D9: =INDEX('تحليل التكلفة والسعر'!$C$2:$C$700,MATCH($B9,'تحليل التكلفة والسعر'!$B$2:$B$700,0)) -> 29 | E9: =D9-C9 -> -15 | F9: =IF(C9=0,"",D9/C9-1) -> -0.34090909 | G9: 120 | H9: =INDEX('تحليل التكلفة والسعر'!$D$2:$D$700,MATCH($B9,'تحليل التكلفة والسعر'!$B$2:$B$700,0)) -> 130 | I9: =IF(OR(G9="",G9=0),"",C9/G9) -> 0.36666667 | J9: =IF(OR(H9="",H9=0),"",D9/H9) -> 0.22307692 | K9: =IF(OR(I9="",J9=""),"",J9-I9) -> -0.14358974
A10: قسم الإضافات | B10: اضافة شيكولاتة (عام) | C10: 11 | D10: =INDEX('تحليل التكلفة والسعر'!$C$2:$C$700,MATCH($B10,'تحليل التكلفة والسعر'!$B$2:$B$700,0)) -> 12.76582 | E10: =D10-C10 -> 1.76582 | F10: =IF(C10=0,"",D10/C10-1) -> 0.16052909 | G10: 40 | H10: =INDEX('تحليل التكلفة والسعر'!$D$2:$D$700,MATCH($B10,'تحليل التكلفة والسعر'!$B$2:$B$700,0)) -> 50 | I10: =IF(OR(G10="",G10=0),"",C10/G10) -> 0.275 | J10: =IF(OR(H10="",H10=0),"",D10/H10) -> 0.2553164 | K10: =IF(OR(I10="",J10=""),"",J10-I10) -> -0.0196836
A11: قسم الفطير الحادق الصيامي | B11: فطيرة مشروم صيامي مخصوص | C11: 81.16345 | D11: =INDEX('تحليل التكلفة والسعر'!$C$2:$C$700,MATCH($B11,'تحليل التكلفة والسعر'!$B$2:$B$700,0)) -> 68.311905 | E11: =D11-C11 -> -12.851545 | F11: =IF(C11=0,"",D11/C11-1) -> -0.15834153 | G11: 160 | H11: =INDEX('تحليل التكلفة والسعر'!$D$2:$D$700,MATCH($B11,'تحليل التكلفة والسعر'!$B$2:$B$700,0)) -> 170 | I11: =IF(OR(G11="",G11=0),"",C11/G11) -> 0.50727156 | J11: =IF(OR(H11="",H11=0),"",D11/H11) -> 0.40183474 | K11: =IF(OR(I11="",J11=""),"",J11-I11) -> -0.10543683
A12: قسم البيتزا | B12: بيتزا فراخ كريسبي رانش حجم اكبر | C12: 117.16985 | D12: =INDEX('تحليل التكلفة والسعر'!$C$2:$C$700,MATCH($B12,'تحليل التكلفة والسعر'!$B$2:$B$700,0)) -> 100.6187 | E12: =D12-C12 -> -16.55115 | F12: =IF(C12=0,"",D12/C12-1) -> -0.14125776 | G12: 220 | H12: =INDEX('تحليل التكلفة والسعر'!$D$2:$D$700,MATCH($B12,'تحليل التكلفة والسعر'!$B$2:$B$700,0)) -> 230 | I12: =IF(OR(G12="",G12=0),"",C12/G12) -> 0.53259023 | J12: =IF(OR(H12="",H12=0),"",D12/H12) -> 0.43747261 | K12: =IF(OR(I12="",J12=""),"",J12-I12) -> -0.095117619
A13: قسم الفطير الحادق الصيامي | B13: فطيرة مشروم صيامي وسط | C13: 56.7633 | D13: =INDEX('تحليل التكلفة والسعر'!$C$2:$C$700,MATCH($B13,'تحليل التكلفة والسعر'!$B$2:$B$700,0)) -> 48.41677 | E13: =D13-C13 -> -8.34653 | F13: =IF(C13=0,"",D13/C13-1) -> -0.14704096 | G13: 105 | H13: =INDEX('تحليل التكلفة والسعر'!$D$2:$D$700,MATCH($B13,'تحليل التكلفة والسعر'!$B$2:$B$700,0)) -> 115 | I13: =IF(OR(G13="",G13=0),"",C13/G13) -> 0.54060286 | J13: =IF(OR(H13="",H13=0),"",D13/H13) -> 0.42101539 | K13: =IF(OR(I13="",J13=""),"",J13-I13) -> -0.11958747
A14: قسم البيتزا الصيامي | B14: بيتزا مشروم صيامي مخصوص | C14: 82.84165 | D14: =INDEX('تحليل التكلفة والسعر'!$C$2:$C$700,MATCH($B14,'تحليل التكلفة والسعر'!$B$2:$B$700,0)) -> 70.831905 | E14: =D14-C14 -> -12.009745 | F14: =IF(C14=0,"",D14/C14-1) -> -0.14497231 | G14: 160 | H14: =INDEX('تحليل التكلفة والسعر'!$D$2:$D$700,MATCH($B14,'تحليل التكلفة والسعر'!$B$2:$B$700,0)) -> 170 | I14: =IF(OR(G14="",G14=0),"",C14/G14) -> 0.51776031 | J14: =IF(OR(H14="",H14=0),"",D14/H14) -> 0.41665826 | K14: =IF(OR(I14="",J14=""),"",J14-I14) -> -0.10110205
A15: قسم المشروبات | B15: بيبسي لتر | C15: 35 | D15: =INDEX('تحليل التكلفة والسعر'!$C$2:$C$700,MATCH($B15,'تحليل التكلفة والسعر'!$B$2:$B$700,0)) -> 30 | E15: =D15-C15 -> -5 | F15: =IF(C15=0,"",D15/C15-1) -> -0.14285714 | G15: 35 | H15: =INDEX('تحليل التكلفة والسعر'!$D$2:$D$700,MATCH($B15,'تحليل التكلفة والسعر'!$B$2:$B$700,0)) -> 35 | I15: =IF(OR(G15="",G15=0),"",C15/G15) -> 1 | J15: =IF(OR(H15="",H15=0),"",D15/H15) -> 0.85714286 | K15: =IF(OR(I15="",J15=""),"",J15-I15) -> -0.14285714
A16: قسم الفطير الحادق | B16: فطيرة فراخ كريسبي رانش حجم اكبر | C16: 111.49165 | D16: =INDEX('تحليل التكلفة والسعر'!$C$2:$C$700,MATCH($B16,'تحليل التكلفة والسعر'!$B$2:$B$700,0)) -> 95.9592 | E16: =D16-C16 -> -15.53245 | F16: =IF(C16=0,"",D16/C16-1) -> -0.13931492 | G16: 220 | H16: =INDEX('تحليل التكلفة والسعر'!$D$2:$D$700,MATCH($B16,'تحليل التكلفة والسعر'!$B$2:$B$700,0)) -> 230 | I16: =IF(OR(G16="",G16=0),"",C16/G16) -> 0.50678023 | J16: =IF(OR(H16="",H16=0),"",D16/H16) -> 0.41721391 | K16: =IF(OR(I16="",J16=""),"",J16-I16) -> -0.089566314
... A175: قسم الإضافات | B175: صوص رانش إضافي (L) | C175: 15.75 | D175: =INDEX('تحليل التكلفة والسعر'!$C$2:$C$700,MATCH($B175,'تحليل التكلفة والسعر'!$B$2:$B$700,0)) -> 15.75 | E175: =D175-C175 -> 0 | F175: =IF(C175=0,"",D175/C175-1) -> 0 | G175: 31.25 | H175: =INDEX('تحليل التكلفة والسعر'!$D$2:$D$700,MATCH($B175,'تحليل التكلفة والسعر'!$B$2:$B$700,0)) -> 41.25 | I175: =IF(OR(G175="",G175=0),"",C175/G175) -> 0.504 | J175: =IF(OR(H175="",H175=0),"",D175/H175) -> 0.38181818 | K175: =IF(OR(I175="",J175=""),"",J175-I175) -> -0.12218182

Sheet المنيو
A1: التصنيف | B1: اسم الصنف | C1: سعر البيع الحالي (جنيه)
A2: قسم البيتزا | B2: بيتزا مارجريتا وسط | C2: 90
A3: قسم البيتزا | B3: بيتزا مارجريتا حجم اكبر | C3: 120
A4: قسم البيتزا | B4: بيتزا بسطرمة وسط | C4: 140
A5: قسم البيتزا | B5: بيتزا بسطرمة حجم اكبر | C5: 200
A6: قسم البيتزا | B6: بيتزا سدق وسط | C6: 130
A7: قسم البيتزا | B7: بيتزا سدق حجم اكبر | C7: 190
A8: قسم البيتزا | B8: بيتزا دبل سلامي / بيبروني وسط | C8: 130
A9: قسم البيتزا | B9: بيتزا دبل سلامي / بيبروني حجم اكبر | C9: 190
A10: قسم البيتزا | B10: بيتزا مشكل جبن وسط | C10: 130
A11: قسم البيتزا | B11: بيتزا مشكل جبن حجم اكبر | C11: 190
A12: قسم البيتزا | B12: بيتزا فراخ رانش وسط | C12: 150
A13: قسم البيتزا | B13: بيتزا فراخ رانش حجم اكبر | C13: 230
... A190: قسم المشروبات | B190: مياه معدنية M | C190: 8

Sheet الريسبي
A1: اسم الصنف (من المنيو) | B1: اسم المكون (من المكونات) | C1: الكمية المستخدمة | D1: الوحدة | E1: تكلفة الوحدة (جنيه) | F1: تكلفة السطر (جنيه)
A2: بيتزا مارجريتا وسط | B2: عجين بيتزا | C2: 0.22 | D2: =IFERROR(INDEX(المكونات!$B$2:$B$500,MATCH($B2,المكونات!$A$2:$A$500,0)),"") -> كجم | E2: =IFERROR(INDEX(المكونات!$C$2:$C$500,MATCH($B2,المكونات!$A$2:$A$500,0)),"") -> 22 | F2: =IFERROR($C2*$E2,"") -> 4.84
A3: بيتزا مارجريتا وسط | B3: صلصة مصنع | C3: 0.04 | D3: =IFERROR(INDEX(المكونات!$B$2:$B$500,MATCH($B3,المكونات!$A$2:$A$500,0)),"") -> كجم | E3: =IFERROR(INDEX(المكونات!$C$2:$C$500,MATCH($B3,المكونات!$A$2:$A$500,0)),"") -> 32 | F3: =IFERROR($C3*$E3,"") -> 1.28
A4: بيتزا مارجريتا وسط | B4: طماطم | C4: 0.03 | D4: =IFERROR(INDEX(المكونات!$B$2:$B$500,MATCH($B4,المكونات!$A$2:$A$500,0)),"") -> كجم | E4: =IFERROR(INDEX(المكونات!$C$2:$C$500,MATCH($B4,المكونات!$A$2:$A$500,0)),"") -> 21 | F4: =IFERROR($C4*$E4,"") -> 0.63
A5: بيتزا مارجريتا وسط | B5: فلفل كوبي | C5: 0.02 | D5: =IFERROR(INDEX(المكونات!$B$2:$B$500,MATCH($B5,المكونات!$A$2:$A$500,0)),"") -> كجم | E5: =IFERROR(INDEX(المكونات!$C$2:$C$500,MATCH($B5,المكونات!$A$2:$A$500,0)),"") -> 27 | F5: =IFERROR($C5*$E5,"") -> 0.54
A6: بيتزا مارجريتا وسط | B6: زيتون | C6: 0.02 | D6: =IFERROR(INDEX(المكونات!$B$2:$B$500,MATCH($B6,المكونات!$A$2:$A$500,0)),"") -> كجم | E6: =IFERROR(INDEX(المكونات!$C$2:$C$500,MATCH($B6,المكونات!$A$2:$A$500,0)),"") -> 95 | F6: =IFERROR($C6*$E6,"") -> 1.9
A7: بيتزا مارجريتا وسط | B7: برسيون موتزريلا بيتزا صغير | C7: 1 | D7: =IFERROR(INDEX(المكونات!$B$2:$B$500,MATCH($B7,المكونات!$A$2:$A$500,0)),"") -> قطعة | E7: =IFERROR(INDEX(المكونات!$C$2:$C$500,MATCH($B7,المكونات!$A$2:$A$500,0)),"") -> 20 | F7: =IFERROR($C7*$E7,"") -> 20
A8: بيتزا مارجريتا وسط | B8: علب بيتزا وسط | C8: 1 | D8: =IFERROR(INDEX(المكونات!$B$2:$B$500,MATCH($B8,المكونات!$A$2:$A$500,0)),"") -> قطعة | E8: =IFERROR(INDEX(المكونات!$C$2:$C$500,MATCH($B8,المكونات!$A$2:$A$500,0)),"") -> 4.5 | F8: =IFERROR($C8*$E8,"") -> 4.5
A9: بيتزا مارجريتا وسط | B9: كاتشب ظرف | C9: 2 | D9: =IFERROR(INDEX(المكونات!$B$2:$B$500,MATCH($B9,المكونات!$A$2:$A$500,0)),"") -> قطعة | E9: =IFERROR(INDEX(المكونات!$C$2:$C$500,MATCH($B9,المكونات!$A$2:$A$500,0)),"") -> 0.3 | F9: =IFERROR($C9*$E9,"") -> 0.6
A10: بيتزا مارجريتا وسط | B10: ورق زبدة وسط كيلو 500 ورقة | C10: 1 | D10: =IFERROR(INDEX(المكونات!$B$2:$B$500,MATCH($B10,المكونات!$A$2:$A$500,0)),"") -> قطعة (ورقة) | E10: =IFERROR(INDEX(المكونات!$C$2:$C$500,MATCH($B10,المكونات!$A$2:$A$500,0)),"") -> 0.3665 | F10: =IFERROR($C10*$E10,"") -> 0.3665
A11: بيتزا مارجريتا وسط | B11: اكياس مطبوعة كبير | C11: 1 | D11: =IFERROR(INDEX(المكونات!$B$2:$B$500,MATCH($B11,المكونات!$A$2:$A$500,0)),"") -> قطعة (كيس) | E11: =IFERROR(INDEX(المكونات!$C$2:$C$500,MATCH($B11,المكونات!$A$2:$A$500,0)),"") -> 1.4 | F11: =IFERROR($C11*$E11,"") -> 1.4
A12: بيتزا مارجريتا وسط | B12: كراسي بيتزا | C12: 1 | D12: =IFERROR(INDEX(المكونات!$B$2:$B$500,MATCH($B12,المكونات!$A$2:$A$500,0)),"") -> قطعة | E12: =IFERROR(INDEX(المكونات!$C$2:$C$500,MATCH($B12,المكونات!$A$2:$A$500,0)),"") -> 0.5 | F12: =IFERROR($C12*$E12,"") -> 0.5
A13: بيتزا مارجريتا وسط | B13: جلافزات شفاف | C13: 2 | D13: =IFERROR(INDEX(المكونات!$B$2:$B$500,MATCH($B13,المكونات!$A$2:$A$500,0)),"") -> قطعة (جلفز) | E13: =IFERROR(INDEX(المكونات!$C$2:$C$500,MATCH($B13,المكونات!$A$2:$A$500,0)),"") -> 0.18 | F13: =IFERROR($C13*$E13,"") -> 0.36
... A1743: مياه معدنية M | B1743: مياة معدنية صغير | C1743: 1 | D1743: =IFERROR(INDEX(المكونات!$B$2:$B$500,MATCH($B1743,المكونات!$A$2:$A$500,0)),"") -> قطعة | E1743: =IFERROR(INDEX(المكونات!$C$2:$C$500,MATCH($B1743,المكونات!$A$2:$A$500,0)),"") -> 7 | F1743: =IFERROR($C1743*$E1743,"") -> 7
D1744: =IFERROR(INDEX(المكونات!$B$2:$B$500,MATCH($B1744,المكونات!$A$2:$A$500,0)),"") | E1744: =IFERROR(INDEX(المكونات!$C$2:$C$500,MATCH($B1744,المكونات!$A$2:$A$500,0)),"") | F1744: =IFERROR($C1744*$E1744,"")
D1745: =IFERROR(INDEX(المكونات!$B$2:$B$500,MATCH($B1745,المكونات!$A$2:$A$500,0)),"") | E1745: =IFERROR(INDEX(المكونات!$C$2:$C$500,MATCH($B1745,المكونات!$A$2:$A$500,0)),"") | F1745: =IFERROR($C1745*$E1745,"")
D1746: =IFERROR(INDEX(المكونات!$B$2:$B$500,MATCH($B1746,المكونات!$A$2:$A$500,0)),"") | E1746: =IFERROR(INDEX(المكونات!$C$2:$C$500,MATCH($B1746,المكونات!$A$2:$A$500,0)),"") | F1746: =IFERROR($C1746*$E1746,"")
D1747: =IFERROR(INDEX(المكونات!$B$2:$B$500,MATCH($B1747,المكونات!$A$2:$A$500,0)),"") | E1747: =IFERROR(INDEX(المكونات!$C$2:$C$500,MATCH($B1747,المكونات!$A$2:$A$500,0)),"") | F1747: =IFERROR($C1747*$E1747,"")
D1748: =IFERROR(INDEX(المكونات!$B$2:$B$500,MATCH($B1748,المكونات!$A$2:$A$500,0)),"") | E1748: =IFERROR(INDEX(المكونات!$C$2:$C$500,MATCH($B1748,المكونات!$A$2:$A$500,0)),"") | F1748: =IFERROR($C1748*$E1748,"")
D1749: =IFERROR(INDEX(المكونات!$B$2:$B$500,MATCH($B1749,المكونات!$A$2:$A$500,0)),"") | E1749: =IFERROR(INDEX(المكونات!$C$2:$C$500,MATCH($B1749,المكونات!$A$2:$A$500,0)),"") | F1749: =IFERROR($C1749*$E1749,"")
D1750: =IFERROR(INDEX(المكونات!$B$2:$B$500,MATCH($B1750,المكونات!$A$2:$A$500,0)),"") | E1750: =IFERROR(INDEX(المكونات!$C$2:$C$500,MATCH($B1750,المكونات!$A$2:$A$500,0)),"") | F1750: =IFERROR($C1750*$E1750,"")
D1751: =IFERROR(INDEX(المكونات!$B$2:$B$500,MATCH($B1751,المكونات!$A$2:$A$500,0)),"") | E1751: =IFERROR(INDEX(المكونات!$C$2:$C$500,MATCH($B1751,المكونات!$A$2:$A$500,0)),"") | F1751: =IFERROR($C1751*$E1751,"")
D1752: =IFERROR(INDEX(المكونات!$B$2:$B$500,MATCH($B1752,المكونات!$A$2:$A$500,0)),"") | E1752: =IFERROR(INDEX(المكونات!$C$2:$C$500,MATCH($B1752,المكونات!$A$2:$A$500,0)),"") | F1752: =IFERROR($C1752*$E1752,"")
D1753: =IFERROR(INDEX(المكونات!$B$2:$B$500,MATCH($B1753,المكونات!$A$2:$A$500,0)),"") | E1753: =IFERROR(INDEX(المكونات!$C$2:$C$500,MATCH($B1753,المكونات!$A$2:$A$500,0)),"") | F1753: =IFERROR($C1753*$E1753,"")
D1754: =IFERROR(INDEX(المكونات!$B$2:$B$500,MATCH($B1754,المكونات!$A$2:$A$500,0)),"") | E1754: =IFERROR(INDEX(المكونات!$C$2:$C$500,MATCH($B1754,المكونات!$A$2:$A$500,0)),"") | F1754: =IFERROR($C1754*$E1754,"")
D1755: =IFERROR(INDEX(المكونات!$B$2:$B$500,MATCH($B1755,المكونات!$A$2:$A$500,0)),"") | E1755: =IFERROR(INDEX(المكونات!$C$2:$C$500,MATCH($B1755,المكونات!$A$2:$A$500,0)),"") | F1755: =IFERROR($C1755*$E1755,"")
... D1799: =IFERROR(INDEX(المكونات!$B$2:$B$500,MATCH($B1799,المكونات!$A$2:$A$500,0)),"") | E1799: =IFERROR(INDEX(المكونات!$C$2:$C$500,MATCH($B1799,المكونات!$A$2:$A$500,0)),"") | F1799: =IFERROR($C1799*$E1799,"")

Sheet تحليل التكلفة والسعر
A1: التصنيف | B1: اسم الصنف | C1: تكلفة الريسبي الكلية (جنيه) | D1: سعر البيع الحالي (جنيه) | E1: % تكلفة الطعام (من سعر البيع) | F1: النسبة المستهدفة | G1: السعر العادل لتحقيق الهدف (جنيه) | H1: الربح لكل صنف (جنيه) | I1: % هامش الربح | J1: % تكلفة العمالة المقدرة | K1: % Prime Cost (طعام + عمالة) | L1: مساعد ترتيب (مخفي) | M1: تكلفة إضافية معيارية للوحدة (جنيه) | N1: إجمالي التكلفة شاملة الأوفرهيد (جنيه)
A2: =IFERROR(IF(المنيو!$B2="","",المنيو!$A2),"") -> قسم البيتزا | B2: =IFERROR(المنيو!$B2,"") -> بيتزا مارجريتا وسط | C2: =IFERROR(IF($B2="","",SUMIFS(الريسبي!$F$2:$F$1800,الريسبي!$A$2:$A$1800,$B2)),"") -> 37.9165 | D2: =IFERROR(IF($B2="","",المنيو!$C2),"") -> 90 | E2: =IFERROR(IF(OR($B2="",$D2=0,$D2=""),"",$N2/$D2),"") -> 0.43164889 | F2: 0.375 | G2: =IFERROR(IF($B2="","",$N2/$F2),"") -> 103.59573 | H2: =IFERROR(IF($B2="","",$D2-$N2),"") -> 51.1516 | I2: =IFERROR(IF(OR($B2="",$D2=0,$D2=""),"",$H2/$D2),"") -> 0.56835111 | J2: 0.25 | K2: =IFERROR(IF($B2="","",$E2+$J2),"") -> 0.68164889 | L2: =IFERROR(IF(OR($B2="",$C2=0,$C2=""),"",$I2+ROW()*0.0000001),"") -> 0.56835131 | M2: 0.9319 | N2: =IFERROR(IF($B2="","",$C2+$M2),"") -> 38.8484
A3: =IFERROR(IF(المنيو!$B3="","",المنيو!$A3),"") -> قسم البيتزا | B3: =IFERROR(المنيو!$B3,"") -> بيتزا مارجريتا حجم اكبر | C3: =IFERROR(IF($B3="","",SUMIFS(الريسبي!$F$2:$F$1800,الريسبي!$A$2:$A$1800,$B3)),"") -> 50.291 | D3: =IFERROR(IF($B3="","",المنيو!$C3),"") -> 120 | E3: =IFERROR(IF(OR($B3="",$D3=0,$D3=""),"",$N3/$D3),"") -> 0.4268575 | F3: =$F$2 -> 0.375 | G3: =IFERROR(IF($B3="","",$N3/$F3),"") -> 136.5944 | H3: =IFERROR(IF($B3="","",$D3-$N3),"") -> 68.7771 | I3: =IFERROR(IF(OR($B3="",$D3=0,$D3=""),"",$H3/$D3),"") -> 0.5731425 | J3: =$J$2 -> 0.25 | K3: =IFERROR(IF($B3="","",$E3+$J3),"") -> 0.6768575 | L3: =IFERROR(IF(OR($B3="",$C3=0,$C3=""),"",$I3+ROW()*0.0000001),"") -> 0.5731428 | M3: =$M$2 -> 0.9319 | N3: =IFERROR(IF($B3="","",$C3+$M3),"") -> 51.2229
